06-04-25 15:45:13 - ERROR - [Errno 13] Permission denied: 'C:\\Users\\sumit\\BotKapil\\BotKapil\\data/ZohoWorkDrive/01-2025/NIFTY_I.csv'
Traceback (most recent call last):
  File "C:\Users\sumit\BotKapil\BotKapil\utility\utility.py", line 129, in gettestdata
    df= pd.read_json(logpath)
  File "C:\Users\sumit\BotKapil\Lib\site-packages\pandas\io\json\_json.py", line 791, in read_json
    json_reader = JsonReader(
        path_or_buf,
    ...<16 lines>...
        engine=engine,
    )
  File "C:\Users\sumit\BotKapil\Lib\site-packages\pandas\io\json\_json.py", line 904, in __init__
    data = self._get_data_from_filepath(filepath_or_buffer)
  File "C:\Users\sumit\BotKapil\Lib\site-packages\pandas\io\json\_json.py", line 944, in _get_data_from_filepath
    self.handles = get_handle(
                   ~~~~~~~~~~^
        filepath_or_buffer,
        ^^^^^^^^^^^^^^^^^^^
    ...<4 lines>...
        errors=self.encoding_errors,
        ^^^^^^^^^^^^^^^^^^^^^^^^^^^^
    )
    ^
  File "C:\Users\sumit\BotKapil\Lib\site-packages\pandas\io\common.py", line 873, in get_handle
    handle = open(
        handle,
    ...<3 lines>...
        newline="",
    )
PermissionError: [Errno 13] Permission denied: 'C:\\Users\\sumit\\BotKapil\\BotKapil\\data/ZohoWorkDrive/01-2025/NIFTY_I.csv'
06-04-25 15:46:02 - ERROR - [Errno 13] Permission denied: 'C:\\Users\\sumit\\BotKapil\\BotKapil\\data/ZohoWorkDrive/01-2025/NIFTY_I.csv'
Traceback (most recent call last):
  File "C:\Users\sumit\BotKapil\BotKapil\utility\utility.py", line 129, in gettestdata
    df= pd.read_json(logpath)
  File "C:\Users\sumit\BotKapil\Lib\site-packages\pandas\io\json\_json.py", line 791, in read_json
    json_reader = JsonReader(
        path_or_buf,
    ...<16 lines>...
        engine=engine,
    )
  File "C:\Users\sumit\BotKapil\Lib\site-packages\pandas\io\json\_json.py", line 904, in __init__
    data = self._get_data_from_filepath(filepath_or_buffer)
  File "C:\Users\sumit\BotKapil\Lib\site-packages\pandas\io\json\_json.py", line 944, in _get_data_from_filepath
    self.handles = get_handle(
                   ~~~~~~~~~~^
        filepath_or_buffer,
        ^^^^^^^^^^^^^^^^^^^
    ...<4 lines>...
        errors=self.encoding_errors,
        ^^^^^^^^^^^^^^^^^^^^^^^^^^^^
    )
    ^
  File "C:\Users\sumit\BotKapil\Lib\site-packages\pandas\io\common.py", line 873, in get_handle
    handle = open(
        handle,
    ...<3 lines>...
        newline="",
    )
PermissionError: [Errno 13] Permission denied: 'C:\\Users\\sumit\\BotKapil\\BotKapil\\data/ZohoWorkDrive/01-2025/NIFTY_I.csv'
06-04-25 15:47:19 - ERROR - Expected object or value
Traceback (most recent call last):
  File "C:\Users\sumit\BotKapil\BotKapil\utility\utility.py", line 129, in gettestdata
    df= pd.read_json(datapath)
  File "C:\Users\sumit\BotKapil\Lib\site-packages\pandas\io\json\_json.py", line 815, in read_json
    return json_reader.read()
           ~~~~~~~~~~~~~~~~^^
  File "C:\Users\sumit\BotKapil\Lib\site-packages\pandas\io\json\_json.py", line 1025, in read
    obj = self._get_object_parser(self.data)
  File "C:\Users\sumit\BotKapil\Lib\site-packages\pandas\io\json\_json.py", line 1051, in _get_object_parser
    obj = FrameParser(json, **kwargs).parse()
  File "C:\Users\sumit\BotKapil\Lib\site-packages\pandas\io\json\_json.py", line 1187, in parse
    self._parse()
    ~~~~~~~~~~~^^
  File "C:\Users\sumit\BotKapil\Lib\site-packages\pandas\io\json\_json.py", line 1403, in _parse
    ujson_loads(json, precise_float=self.precise_float), dtype=None
    ~~~~~~~~~~~^^^^^^^^^^^^^^^^^^^^^^^^^^^^^^^^^^^^^^^^
ValueError: Expected object or value
06-04-25 15:48:17 - ERROR - Expected object or value
Traceback (most recent call last):
  File "C:\Users\sumit\BotKapil\BotKapil\utility\utility.py", line 130, in gettestdata
    df= pd.read_json(datapath)
  File "C:\Users\sumit\BotKapil\Lib\site-packages\pandas\io\json\_json.py", line 815, in read_json
    return json_reader.read()
           ~~~~~~~~~~~~~~~~^^
  File "C:\Users\sumit\BotKapil\Lib\site-packages\pandas\io\json\_json.py", line 1025, in read
    obj = self._get_object_parser(self.data)
  File "C:\Users\sumit\BotKapil\Lib\site-packages\pandas\io\json\_json.py", line 1051, in _get_object_parser
    obj = FrameParser(json, **kwargs).parse()
  File "C:\Users\sumit\BotKapil\Lib\site-packages\pandas\io\json\_json.py", line 1187, in parse
    self._parse()
    ~~~~~~~~~~~^^
  File "C:\Users\sumit\BotKapil\Lib\site-packages\pandas\io\json\_json.py", line 1403, in _parse
    ujson_loads(json, precise_float=self.precise_float), dtype=None
    ~~~~~~~~~~~^^^^^^^^^^^^^^^^^^^^^^^^^^^^^^^^^^^^^^^^
ValueError: Expected object or value
06-04-25 15:49:06 - ERROR - unsupported operand type(s) for +: 'int' and 'str'
Traceback (most recent call last):
  File "C:\Users\sumit\BotKapil\Lib\site-packages\pandas\core\ops\array_ops.py", line 218, in _na_arithmetic_op
    result = func(left, right)
  File "C:\Users\sumit\BotKapil\Lib\site-packages\pandas\core\computation\expressions.py", line 242, in evaluate
    return _evaluate(op, op_str, a, b)  # type: ignore[misc]
  File "C:\Users\sumit\BotKapil\Lib\site-packages\pandas\core\computation\expressions.py", line 131, in _evaluate_numexpr
    result = _evaluate_standard(op, op_str, a, b)
  File "C:\Users\sumit\BotKapil\Lib\site-packages\pandas\core\computation\expressions.py", line 73, in _evaluate_standard
    return op(a, b)
TypeError: unsupported operand type(s) for +: 'int' and 'str'

During handling of the above exception, another exception occurred:

Traceback (most recent call last):
  File "C:\Users\sumit\BotKapil\BotKapil\utility\utility.py", line 141, in buildcandels
    data['updated_at'] = pd.to_datetime(data['Date']+data['Time'])
                                        ~~~~~~~~~~~~^~~~~~~~~~~~~
  File "C:\Users\sumit\BotKapil\Lib\site-packages\pandas\core\ops\common.py", line 76, in new_method
    return method(self, other)
  File "C:\Users\sumit\BotKapil\Lib\site-packages\pandas\core\arraylike.py", line 186, in __add__
    return self._arith_method(other, operator.add)
           ~~~~~~~~~~~~~~~~~~^^^^^^^^^^^^^^^^^^^^^
  File "C:\Users\sumit\BotKapil\Lib\site-packages\pandas\core\series.py", line 6135, in _arith_method
    return base.IndexOpsMixin._arith_method(self, other, op)
           ~~~~~~~~~~~~~~~~~~~~~~~~~~~~~~~~^^^^^^^^^^^^^^^^^
  File "C:\Users\sumit\BotKapil\Lib\site-packages\pandas\core\base.py", line 1382, in _arith_method
    result = ops.arithmetic_op(lvalues, rvalues, op)
  File "C:\Users\sumit\BotKapil\Lib\site-packages\pandas\core\ops\array_ops.py", line 283, in arithmetic_op
    res_values = _na_arithmetic_op(left, right, op)  # type: ignore[arg-type]
  File "C:\Users\sumit\BotKapil\Lib\site-packages\pandas\core\ops\array_ops.py", line 227, in _na_arithmetic_op
    result = _masked_arith_op(left, right, op)
  File "C:\Users\sumit\BotKapil\Lib\site-packages\pandas\core\ops\array_ops.py", line 163, in _masked_arith_op
    result[mask] = op(xrav[mask], yrav[mask])
                   ~~^^^^^^^^^^^^^^^^^^^^^^^^
TypeError: unsupported operand type(s) for +: 'int' and 'str'
06-04-25 15:50:30 - ERROR - Unknown datetime string format, unable to parse: 0         20250101
1         20250101
2         20250101
3         20250101
4         20250101
            ...   
152703    20250117
152704    20250117
152705    20250117
152706    20250117
152707    20250117
Name: Date, Length: 152708, dtype: int640         09:15:00
1         09:15:00
2         09:15:00
3         09:15:00
4         09:15:01
            ...   
152703    15:29:53
152704    15:29:55
152705    15:29:57
152706    15:29:58
152707    15:30:00
Name: Time, Length: 152708, dtype: object, at position 0
Traceback (most recent call last):
  File "C:\Users\sumit\BotKapil\BotKapil\utility\utility.py", line 141, in buildcandels
    data['updated_at'] = pd.to_datetime(str(data['Date'])+str(data['Time']))
                         ~~~~~~~~~~~~~~^^^^^^^^^^^^^^^^^^^^^^^^^^^^^^^^^^^^^
  File "C:\Users\sumit\BotKapil\Lib\site-packages\pandas\core\tools\datetimes.py", line 1101, in to_datetime
    result = convert_listlike(np.array([arg]), format)[0]
             ~~~~~~~~~~~~~~~~^^^^^^^^^^^^^^^^^^^^^^^^^
  File "C:\Users\sumit\BotKapil\Lib\site-packages\pandas\core\tools\datetimes.py", line 435, in _convert_listlike_datetimes
    result, tz_parsed = objects_to_datetime64(
                        ~~~~~~~~~~~~~~~~~~~~~^
        arg,
        ^^^^
    ...<4 lines>...
        allow_object=True,
        ^^^^^^^^^^^^^^^^^^
    )
    ^
  File "C:\Users\sumit\BotKapil\Lib\site-packages\pandas\core\arrays\datetimes.py", line 2398, in objects_to_datetime64
    result, tz_parsed = tslib.array_to_datetime(
                        ~~~~~~~~~~~~~~~~~~~~~~~^
        data,
        ^^^^^
    ...<4 lines>...
        creso=abbrev_to_npy_unit(out_unit),
        ^^^^^^^^^^^^^^^^^^^^^^^^^^^^^^^^^^^
    )
    ^
  File "tslib.pyx", line 414, in pandas._libs.tslib.array_to_datetime
  File "tslib.pyx", line 596, in pandas._libs.tslib.array_to_datetime
  File "tslib.pyx", line 553, in pandas._libs.tslib.array_to_datetime
  File "conversion.pyx", line 641, in pandas._libs.tslibs.conversion.convert_str_to_tsobject
  File "parsing.pyx", line 336, in pandas._libs.tslibs.parsing.parse_datetime_string
  File "parsing.pyx", line 666, in pandas._libs.tslibs.parsing.dateutil_parse
pandas._libs.tslibs.parsing.DateParseError: Unknown datetime string format, unable to parse: 0         20250101
1         20250101
2         20250101
3         20250101
4         20250101
            ...   
152703    20250117
152704    20250117
152705    20250117
152706    20250117
152707    20250117
Name: Date, Length: 152708, dtype: int640         09:15:00
1         09:15:00
2         09:15:00
3         09:15:00
4         09:15:01
            ...   
152703    15:29:53
152704    15:29:55
152705    15:29:57
152706    15:29:58
152707    15:30:00
Name: Time, Length: 152708, dtype: object, at position 0
06-04-25 15:51:27 - ERROR - Unknown datetime string format, unable to parse: 0         20250101
1         20250101
2         20250101
3         20250101
4         20250101
            ...   
152703    20250117
152704    20250117
152705    20250117
152706    20250117
152707    20250117
Name: Date, Length: 152708, dtype: int640         09:15:00
1         09:15:00
2         09:15:00
3         09:15:00
4         09:15:01
            ...   
152703    15:29:53
152704    15:29:55
152705    15:29:57
152706    15:29:58
152707    15:30:00
Name: Time, Length: 152708, dtype: object, at position 0
Traceback (most recent call last):
  File "C:\Users\sumit\BotKapil\BotKapil\utility\utility.py", line 141, in buildcandels
    data['updated_at'] = pd.to_datetime(str(data['Date'])+str(data['Time']))
                         ~~~~~~~~~~~~~~^^^^^^^^^^^^^^^^^^^^^^^^^^^^^^^^^^^^^
  File "C:\Users\sumit\BotKapil\Lib\site-packages\pandas\core\tools\datetimes.py", line 1101, in to_datetime
    result = convert_listlike(np.array([arg]), format)[0]
             ~~~~~~~~~~~~~~~~^^^^^^^^^^^^^^^^^^^^^^^^^
  File "C:\Users\sumit\BotKapil\Lib\site-packages\pandas\core\tools\datetimes.py", line 435, in _convert_listlike_datetimes
    result, tz_parsed = objects_to_datetime64(
                        ~~~~~~~~~~~~~~~~~~~~~^
        arg,
        ^^^^
    ...<4 lines>...
        allow_object=True,
        ^^^^^^^^^^^^^^^^^^
    )
    ^
  File "C:\Users\sumit\BotKapil\Lib\site-packages\pandas\core\arrays\datetimes.py", line 2398, in objects_to_datetime64
    result, tz_parsed = tslib.array_to_datetime(
                        ~~~~~~~~~~~~~~~~~~~~~~~^
        data,
        ^^^^^
    ...<4 lines>...
        creso=abbrev_to_npy_unit(out_unit),
        ^^^^^^^^^^^^^^^^^^^^^^^^^^^^^^^^^^^
    )
    ^
  File "tslib.pyx", line 414, in pandas._libs.tslib.array_to_datetime
  File "tslib.pyx", line 596, in pandas._libs.tslib.array_to_datetime
  File "tslib.pyx", line 553, in pandas._libs.tslib.array_to_datetime
  File "conversion.pyx", line 641, in pandas._libs.tslibs.conversion.convert_str_to_tsobject
  File "parsing.pyx", line 336, in pandas._libs.tslibs.parsing.parse_datetime_string
  File "parsing.pyx", line 666, in pandas._libs.tslibs.parsing.dateutil_parse
pandas._libs.tslibs.parsing.DateParseError: Unknown datetime string format, unable to parse: 0         20250101
1         20250101
2         20250101
3         20250101
4         20250101
            ...   
152703    20250117
152704    20250117
152705    20250117
152706    20250117
152707    20250117
Name: Date, Length: 152708, dtype: int640         09:15:00
1         09:15:00
2         09:15:00
3         09:15:00
4         09:15:01
            ...   
152703    15:29:53
152704    15:29:55
152705    15:29:57
152706    15:29:58
152707    15:30:00
Name: Time, Length: 152708, dtype: object, at position 0
06-04-25 15:54:49 - ERROR - Unknown datetime string format, unable to parse: 0         20250101
1         20250101
2         20250101
3         20250101
4         20250101
            ...   
152703    20250117
152704    20250117
152705    20250117
152706    20250117
152707    20250117
Name: Date, Length: 152708, dtype: int64, at position 0
Traceback (most recent call last):
  File "C:\Users\sumit\BotKapil\BotKapil\utility\utility.py", line 141, in buildcandels
    date= pd.to_datetime(str(data['Date']))
  File "C:\Users\sumit\BotKapil\Lib\site-packages\pandas\core\tools\datetimes.py", line 1101, in to_datetime
    result = convert_listlike(np.array([arg]), format)[0]
             ~~~~~~~~~~~~~~~~^^^^^^^^^^^^^^^^^^^^^^^^^
  File "C:\Users\sumit\BotKapil\Lib\site-packages\pandas\core\tools\datetimes.py", line 435, in _convert_listlike_datetimes
    result, tz_parsed = objects_to_datetime64(
                        ~~~~~~~~~~~~~~~~~~~~~^
        arg,
        ^^^^
    ...<4 lines>...
        allow_object=True,
        ^^^^^^^^^^^^^^^^^^
    )
    ^
  File "C:\Users\sumit\BotKapil\Lib\site-packages\pandas\core\arrays\datetimes.py", line 2398, in objects_to_datetime64
    result, tz_parsed = tslib.array_to_datetime(
                        ~~~~~~~~~~~~~~~~~~~~~~~^
        data,
        ^^^^^
    ...<4 lines>...
        creso=abbrev_to_npy_unit(out_unit),
        ^^^^^^^^^^^^^^^^^^^^^^^^^^^^^^^^^^^
    )
    ^
  File "tslib.pyx", line 414, in pandas._libs.tslib.array_to_datetime
  File "tslib.pyx", line 596, in pandas._libs.tslib.array_to_datetime
  File "tslib.pyx", line 553, in pandas._libs.tslib.array_to_datetime
  File "conversion.pyx", line 641, in pandas._libs.tslibs.conversion.convert_str_to_tsobject
  File "parsing.pyx", line 336, in pandas._libs.tslibs.parsing.parse_datetime_string
  File "parsing.pyx", line 666, in pandas._libs.tslibs.parsing.dateutil_parse
pandas._libs.tslibs.parsing.DateParseError: Unknown datetime string format, unable to parse: 0         20250101
1         20250101
2         20250101
3         20250101
4         20250101
            ...   
152703    20250117
152704    20250117
152705    20250117
152706    20250117
152707    20250117
Name: Date, Length: 152708, dtype: int64, at position 0
06-04-25 15:55:37 - ERROR - Unknown datetime string format, unable to parse: 0         20250101
1         20250101
2         20250101
3         20250101
4         20250101
            ...   
152703    20250117
152704    20250117
152705    20250117
152706    20250117
152707    20250117
Name: Date, Length: 152708, dtype: int64, at position 0
Traceback (most recent call last):
  File "C:\Users\sumit\BotKapil\BotKapil\utility\utility.py", line 141, in buildcandels
    date= pd.to_datetime(str(data['Date']))
  File "C:\Users\sumit\BotKapil\Lib\site-packages\pandas\core\tools\datetimes.py", line 1101, in to_datetime
    result = convert_listlike(np.array([arg]), format)[0]
             ~~~~~~~~~~~~~~~~^^^^^^^^^^^^^^^^^^^^^^^^^
  File "C:\Users\sumit\BotKapil\Lib\site-packages\pandas\core\tools\datetimes.py", line 435, in _convert_listlike_datetimes
    result, tz_parsed = objects_to_datetime64(
                        ~~~~~~~~~~~~~~~~~~~~~^
        arg,
        ^^^^
    ...<4 lines>...
        allow_object=True,
        ^^^^^^^^^^^^^^^^^^
    )
    ^
  File "C:\Users\sumit\BotKapil\Lib\site-packages\pandas\core\arrays\datetimes.py", line 2398, in objects_to_datetime64
    result, tz_parsed = tslib.array_to_datetime(
                        ~~~~~~~~~~~~~~~~~~~~~~~^
        data,
        ^^^^^
    ...<4 lines>...
        creso=abbrev_to_npy_unit(out_unit),
        ^^^^^^^^^^^^^^^^^^^^^^^^^^^^^^^^^^^
    )
    ^
  File "tslib.pyx", line 414, in pandas._libs.tslib.array_to_datetime
  File "tslib.pyx", line 596, in pandas._libs.tslib.array_to_datetime
  File "tslib.pyx", line 553, in pandas._libs.tslib.array_to_datetime
  File "conversion.pyx", line 641, in pandas._libs.tslibs.conversion.convert_str_to_tsobject
  File "parsing.pyx", line 336, in pandas._libs.tslibs.parsing.parse_datetime_string
  File "parsing.pyx", line 666, in pandas._libs.tslibs.parsing.dateutil_parse
pandas._libs.tslibs.parsing.DateParseError: Unknown datetime string format, unable to parse: 0         20250101
1         20250101
2         20250101
3         20250101
4         20250101
            ...   
152703    20250117
152704    20250117
152705    20250117
152706    20250117
152707    20250117
Name: Date, Length: 152708, dtype: int64, at position 0
06-04-25 15:56:39 - ERROR - Unknown datetime string format, unable to parse: 0         20250101
1         20250101
2         20250101
3         20250101
4         20250101
            ...   
152703    20250117
152704    20250117
152705    20250117
152706    20250117
152707    20250117
Name: Date, Length: 152708, dtype: int64, at position 0
Traceback (most recent call last):
  File "C:\Users\sumit\BotKapil\BotKapil\utility\utility.py", line 141, in buildcandels
    date= pd.to_datetime(str(data['Date']))
  File "C:\Users\sumit\BotKapil\Lib\site-packages\pandas\core\tools\datetimes.py", line 1101, in to_datetime
    result = convert_listlike(np.array([arg]), format)[0]
             ~~~~~~~~~~~~~~~~^^^^^^^^^^^^^^^^^^^^^^^^^
  File "C:\Users\sumit\BotKapil\Lib\site-packages\pandas\core\tools\datetimes.py", line 435, in _convert_listlike_datetimes
    result, tz_parsed = objects_to_datetime64(
                        ~~~~~~~~~~~~~~~~~~~~~^
        arg,
        ^^^^
    ...<4 lines>...
        allow_object=True,
        ^^^^^^^^^^^^^^^^^^
    )
    ^
  File "C:\Users\sumit\BotKapil\Lib\site-packages\pandas\core\arrays\datetimes.py", line 2398, in objects_to_datetime64
    result, tz_parsed = tslib.array_to_datetime(
                        ~~~~~~~~~~~~~~~~~~~~~~~^
        data,
        ^^^^^
    ...<4 lines>...
        creso=abbrev_to_npy_unit(out_unit),
        ^^^^^^^^^^^^^^^^^^^^^^^^^^^^^^^^^^^
    )
    ^
  File "tslib.pyx", line 414, in pandas._libs.tslib.array_to_datetime
  File "tslib.pyx", line 596, in pandas._libs.tslib.array_to_datetime
  File "tslib.pyx", line 553, in pandas._libs.tslib.array_to_datetime
  File "conversion.pyx", line 641, in pandas._libs.tslibs.conversion.convert_str_to_tsobject
  File "parsing.pyx", line 336, in pandas._libs.tslibs.parsing.parse_datetime_string
  File "parsing.pyx", line 666, in pandas._libs.tslibs.parsing.dateutil_parse
pandas._libs.tslibs.parsing.DateParseError: Unknown datetime string format, unable to parse: 0         20250101
1         20250101
2         20250101
3         20250101
4         20250101
            ...   
152703    20250117
152704    20250117
152705    20250117
152706    20250117
152707    20250117
Name: Date, Length: 152708, dtype: int64, at position 0
06-04-25 18:57:02 - ERROR - ufunc 'add' did not contain a loop with signature matching types (dtype('int64'), dtype('<U1')) -> None
Traceback (most recent call last):
  File "C:\Users\sumit\BotKapil\BotKapil\utility\utility.py", line 131, in gettestdata
    df['updated_at']=pd.to_datetime(str(df['Date'][-2:]+'-'+df['Date'][-4:-2]+'-'+df['Date'][0:4]+' '+df['Time']))
                                        ~~~~~~~~~~~~~~~^~~~
  File "C:\Users\sumit\BotKapil\Lib\site-packages\pandas\core\ops\common.py", line 76, in new_method
    return method(self, other)
  File "C:\Users\sumit\BotKapil\Lib\site-packages\pandas\core\arraylike.py", line 186, in __add__
    return self._arith_method(other, operator.add)
           ~~~~~~~~~~~~~~~~~~^^^^^^^^^^^^^^^^^^^^^
  File "C:\Users\sumit\BotKapil\Lib\site-packages\pandas\core\series.py", line 6135, in _arith_method
    return base.IndexOpsMixin._arith_method(self, other, op)
           ~~~~~~~~~~~~~~~~~~~~~~~~~~~~~~~~^^^^^^^^^^^^^^^^^
  File "C:\Users\sumit\BotKapil\Lib\site-packages\pandas\core\base.py", line 1382, in _arith_method
    result = ops.arithmetic_op(lvalues, rvalues, op)
  File "C:\Users\sumit\BotKapil\Lib\site-packages\pandas\core\ops\array_ops.py", line 283, in arithmetic_op
    res_values = _na_arithmetic_op(left, right, op)  # type: ignore[arg-type]
  File "C:\Users\sumit\BotKapil\Lib\site-packages\pandas\core\ops\array_ops.py", line 218, in _na_arithmetic_op
    result = func(left, right)
numpy._core._exceptions._UFuncNoLoopError: ufunc 'add' did not contain a loop with signature matching types (dtype('int64'), dtype('<U1')) -> None
06-04-25 18:58:45 - ERROR - Unknown datetime string format, unable to parse: 64-nt-0    09:15:00, at position 0
Traceback (most recent call last):
  File "C:\Users\sumit\BotKapil\BotKapil\utility\utility.py", line 131, in gettestdata
    df['updated_at']=pd.to_datetime(str(df['Date'])[-2:]+'-'+str(df['Date'])[-4:-2]+'-'+str(df['Date'])[0:4]+' '+df['Time'])
                     ~~~~~~~~~~~~~~^^^^^^^^^^^^^^^^^^^^^^^^^^^^^^^^^^^^^^^^^^^^^^^^^^^^^^^^^^^^^^^^^^^^^^^^^^^^^^^^^^^^^^^^^
  File "C:\Users\sumit\BotKapil\Lib\site-packages\pandas\core\tools\datetimes.py", line 1067, in to_datetime
    values = convert_listlike(arg._values, format)
  File "C:\Users\sumit\BotKapil\Lib\site-packages\pandas\core\tools\datetimes.py", line 435, in _convert_listlike_datetimes
    result, tz_parsed = objects_to_datetime64(
                        ~~~~~~~~~~~~~~~~~~~~~^
        arg,
        ^^^^
    ...<4 lines>...
        allow_object=True,
        ^^^^^^^^^^^^^^^^^^
    )
    ^
  File "C:\Users\sumit\BotKapil\Lib\site-packages\pandas\core\arrays\datetimes.py", line 2398, in objects_to_datetime64
    result, tz_parsed = tslib.array_to_datetime(
                        ~~~~~~~~~~~~~~~~~~~~~~~^
        data,
        ^^^^^
    ...<4 lines>...
        creso=abbrev_to_npy_unit(out_unit),
        ^^^^^^^^^^^^^^^^^^^^^^^^^^^^^^^^^^^
    )
    ^
  File "tslib.pyx", line 414, in pandas._libs.tslib.array_to_datetime
  File "tslib.pyx", line 596, in pandas._libs.tslib.array_to_datetime
  File "tslib.pyx", line 553, in pandas._libs.tslib.array_to_datetime
  File "conversion.pyx", line 641, in pandas._libs.tslibs.conversion.convert_str_to_tsobject
  File "parsing.pyx", line 336, in pandas._libs.tslibs.parsing.parse_datetime_string
  File "parsing.pyx", line 666, in pandas._libs.tslibs.parsing.dateutil_parse
pandas._libs.tslibs.parsing.DateParseError: Unknown datetime string format, unable to parse: 64-nt-0    09:15:00, at position 0
06-04-25 18:59:34 - ERROR - Unknown datetime string format, unable to parse: 64-nt-0    09:15:00, at position 0
Traceback (most recent call last):
  File "C:\Users\sumit\BotKapil\BotKapil\utility\utility.py", line 132, in gettestdata
    df['updated_at']=pd.to_datetime(str(df['Date'])[-2:]+'-'+str(df['Date'])[-4:-2]+'-'+str(df['Date'])[0:4]+' '+df['Time'])
                     ~~~~~~~~~~~~~~^^^^^^^^^^^^^^^^^^^^^^^^^^^^^^^^^^^^^^^^^^^^^^^^^^^^^^^^^^^^^^^^^^^^^^^^^^^^^^^^^^^^^^^^^
  File "C:\Users\sumit\BotKapil\Lib\site-packages\pandas\core\tools\datetimes.py", line 1067, in to_datetime
    values = convert_listlike(arg._values, format)
  File "C:\Users\sumit\BotKapil\Lib\site-packages\pandas\core\tools\datetimes.py", line 435, in _convert_listlike_datetimes
    result, tz_parsed = objects_to_datetime64(
                        ~~~~~~~~~~~~~~~~~~~~~^
        arg,
        ^^^^
    ...<4 lines>...
        allow_object=True,
        ^^^^^^^^^^^^^^^^^^
    )
    ^
  File "C:\Users\sumit\BotKapil\Lib\site-packages\pandas\core\arrays\datetimes.py", line 2398, in objects_to_datetime64
    result, tz_parsed = tslib.array_to_datetime(
                        ~~~~~~~~~~~~~~~~~~~~~~~^
        data,
        ^^^^^
    ...<4 lines>...
        creso=abbrev_to_npy_unit(out_unit),
        ^^^^^^^^^^^^^^^^^^^^^^^^^^^^^^^^^^^
    )
    ^
  File "tslib.pyx", line 414, in pandas._libs.tslib.array_to_datetime
  File "tslib.pyx", line 596, in pandas._libs.tslib.array_to_datetime
  File "tslib.pyx", line 553, in pandas._libs.tslib.array_to_datetime
  File "conversion.pyx", line 641, in pandas._libs.tslibs.conversion.convert_str_to_tsobject
  File "parsing.pyx", line 336, in pandas._libs.tslibs.parsing.parse_datetime_string
  File "parsing.pyx", line 666, in pandas._libs.tslibs.parsing.dateutil_parse
pandas._libs.tslibs.parsing.DateParseError: Unknown datetime string format, unable to parse: 64-nt-0    09:15:00, at position 0
06-04-25 19:00:23 - ERROR - Unknown datetime string format, unable to parse: 64-nt-0    09:15:00, at position 0
Traceback (most recent call last):
  File "C:\Users\sumit\BotKapil\BotKapil\utility\utility.py", line 133, in gettestdata
    df['updated_at']=pd.to_datetime(str(df['Date'])[-2:]+'-'+str(df['Date'])[-4:-2]+'-'+str(df['Date'])[0:4]+' '+df['Time'])
                     ~~~~~~~~~~~~~~^^^^^^^^^^^^^^^^^^^^^^^^^^^^^^^^^^^^^^^^^^^^^^^^^^^^^^^^^^^^^^^^^^^^^^^^^^^^^^^^^^^^^^^^^
  File "C:\Users\sumit\BotKapil\Lib\site-packages\pandas\core\tools\datetimes.py", line 1067, in to_datetime
    values = convert_listlike(arg._values, format)
  File "C:\Users\sumit\BotKapil\Lib\site-packages\pandas\core\tools\datetimes.py", line 435, in _convert_listlike_datetimes
    result, tz_parsed = objects_to_datetime64(
                        ~~~~~~~~~~~~~~~~~~~~~^
        arg,
        ^^^^
    ...<4 lines>...
        allow_object=True,
        ^^^^^^^^^^^^^^^^^^
    )
    ^
  File "C:\Users\sumit\BotKapil\Lib\site-packages\pandas\core\arrays\datetimes.py", line 2398, in objects_to_datetime64
    result, tz_parsed = tslib.array_to_datetime(
                        ~~~~~~~~~~~~~~~~~~~~~~~^
        data,
        ^^^^^
    ...<4 lines>...
        creso=abbrev_to_npy_unit(out_unit),
        ^^^^^^^^^^^^^^^^^^^^^^^^^^^^^^^^^^^
    )
    ^
  File "tslib.pyx", line 414, in pandas._libs.tslib.array_to_datetime
  File "tslib.pyx", line 596, in pandas._libs.tslib.array_to_datetime
  File "tslib.pyx", line 553, in pandas._libs.tslib.array_to_datetime
  File "conversion.pyx", line 641, in pandas._libs.tslibs.conversion.convert_str_to_tsobject
  File "parsing.pyx", line 336, in pandas._libs.tslibs.parsing.parse_datetime_string
  File "parsing.pyx", line 666, in pandas._libs.tslibs.parsing.dateutil_parse
pandas._libs.tslibs.parsing.DateParseError: Unknown datetime string format, unable to parse: 64-nt-0    09:15:00, at position 0
06-04-25 19:01:00 - ERROR - Unknown datetime string format, unable to parse: 64-nt-0    09:15:00, at position 0
Traceback (most recent call last):
  File "C:\Users\sumit\BotKapil\BotKapil\utility\utility.py", line 134, in gettestdata
    df['updated_at']=pd.to_datetime(str(df['Date'])[-2:]+'-'+str(df['Date'])[-4:-2]+'-'+str(df['Date'])[0:4]+' '+df['Time'])
                     ~~~~~~~~~~~~~~^^^^^^^^^^^^^^^^^^^^^^^^^^^^^^^^^^^^^^^^^^^^^^^^^^^^^^^^^^^^^^^^^^^^^^^^^^^^^^^^^^^^^^^^^
  File "C:\Users\sumit\BotKapil\Lib\site-packages\pandas\core\tools\datetimes.py", line 1067, in to_datetime
    values = convert_listlike(arg._values, format)
  File "C:\Users\sumit\BotKapil\Lib\site-packages\pandas\core\tools\datetimes.py", line 435, in _convert_listlike_datetimes
    result, tz_parsed = objects_to_datetime64(
                        ~~~~~~~~~~~~~~~~~~~~~^
        arg,
        ^^^^
    ...<4 lines>...
        allow_object=True,
        ^^^^^^^^^^^^^^^^^^
    )
    ^
  File "C:\Users\sumit\BotKapil\Lib\site-packages\pandas\core\arrays\datetimes.py", line 2398, in objects_to_datetime64
    result, tz_parsed = tslib.array_to_datetime(
                        ~~~~~~~~~~~~~~~~~~~~~~~^
        data,
        ^^^^^
    ...<4 lines>...
        creso=abbrev_to_npy_unit(out_unit),
        ^^^^^^^^^^^^^^^^^^^^^^^^^^^^^^^^^^^
    )
    ^
  File "tslib.pyx", line 414, in pandas._libs.tslib.array_to_datetime
  File "tslib.pyx", line 596, in pandas._libs.tslib.array_to_datetime
  File "tslib.pyx", line 553, in pandas._libs.tslib.array_to_datetime
  File "conversion.pyx", line 641, in pandas._libs.tslibs.conversion.convert_str_to_tsobject
  File "parsing.pyx", line 336, in pandas._libs.tslibs.parsing.parse_datetime_string
  File "parsing.pyx", line 666, in pandas._libs.tslibs.parsing.dateutil_parse
pandas._libs.tslibs.parsing.DateParseError: Unknown datetime string format, unable to parse: 64-nt-0    09:15:00, at position 0
06-04-25 19:01:14 - ERROR - Unknown datetime string format, unable to parse: 64-nt-0    09:15:00, at position 0
Traceback (most recent call last):
  File "C:\Users\sumit\BotKapil\BotKapil\utility\utility.py", line 134, in gettestdata
    df['updated_at']=pd.to_datetime(str(df['Date'])[-2:]+'-'+str(df['Date'])[-4:-2]+'-'+str(df['Date'])[0:4]+' '+df['Time'])
                     ~~~~~~~~~~~~~~^^^^^^^^^^^^^^^^^^^^^^^^^^^^^^^^^^^^^^^^^^^^^^^^^^^^^^^^^^^^^^^^^^^^^^^^^^^^^^^^^^^^^^^^^
  File "C:\Users\sumit\BotKapil\Lib\site-packages\pandas\core\tools\datetimes.py", line 1067, in to_datetime
    values = convert_listlike(arg._values, format)
  File "C:\Users\sumit\BotKapil\Lib\site-packages\pandas\core\tools\datetimes.py", line 435, in _convert_listlike_datetimes
    result, tz_parsed = objects_to_datetime64(
                        ~~~~~~~~~~~~~~~~~~~~~^
        arg,
        ^^^^
    ...<4 lines>...
        allow_object=True,
        ^^^^^^^^^^^^^^^^^^
    )
    ^
  File "C:\Users\sumit\BotKapil\Lib\site-packages\pandas\core\arrays\datetimes.py", line 2398, in objects_to_datetime64
    result, tz_parsed = tslib.array_to_datetime(
                        ~~~~~~~~~~~~~~~~~~~~~~~^
        data,
        ^^^^^
    ...<4 lines>...
        creso=abbrev_to_npy_unit(out_unit),
        ^^^^^^^^^^^^^^^^^^^^^^^^^^^^^^^^^^^
    )
    ^
  File "tslib.pyx", line 414, in pandas._libs.tslib.array_to_datetime
  File "tslib.pyx", line 596, in pandas._libs.tslib.array_to_datetime
  File "tslib.pyx", line 553, in pandas._libs.tslib.array_to_datetime
  File "conversion.pyx", line 641, in pandas._libs.tslibs.conversion.convert_str_to_tsobject
  File "parsing.pyx", line 336, in pandas._libs.tslibs.parsing.parse_datetime_string
  File "parsing.pyx", line 666, in pandas._libs.tslibs.parsing.dateutil_parse
pandas._libs.tslibs.parsing.DateParseError: Unknown datetime string format, unable to parse: 64-nt-0    09:15:00, at position 0
06-04-25 19:04:38 - ERROR - unsupported operand type(s) for +: 'DatetimeArray' and 'str'
Traceback (most recent call last):
  File "C:\Users\sumit\BotKapil\BotKapil\utility\utility.py", line 132, in gettestdata
    df['updated_at']=df['updated_at']+' '+df['Time']
                     ~~~~~~~~~~~~~~~~^~~~
  File "C:\Users\sumit\BotKapil\Lib\site-packages\pandas\core\ops\common.py", line 76, in new_method
    return method(self, other)
  File "C:\Users\sumit\BotKapil\Lib\site-packages\pandas\core\arraylike.py", line 186, in __add__
    return self._arith_method(other, operator.add)
           ~~~~~~~~~~~~~~~~~~^^^^^^^^^^^^^^^^^^^^^
  File "C:\Users\sumit\BotKapil\Lib\site-packages\pandas\core\series.py", line 6135, in _arith_method
    return base.IndexOpsMixin._arith_method(self, other, op)
           ~~~~~~~~~~~~~~~~~~~~~~~~~~~~~~~~^^^^^^^^^^^^^^^^^
  File "C:\Users\sumit\BotKapil\Lib\site-packages\pandas\core\base.py", line 1382, in _arith_method
    result = ops.arithmetic_op(lvalues, rvalues, op)
  File "C:\Users\sumit\BotKapil\Lib\site-packages\pandas\core\ops\array_ops.py", line 273, in arithmetic_op
    res_values = op(left, right)
TypeError: unsupported operand type(s) for +: 'DatetimeArray' and 'str'
06-04-25 19:05:02 - ERROR - unsupported operand type(s) for +: 'DatetimeArray' and 'str'
Traceback (most recent call last):
  File "C:\Users\sumit\BotKapil\BotKapil\utility\utility.py", line 132, in gettestdata
    df['updated_at']=df['updated_at']+' '+df['Time']
                     ~~~~~~~~~~~~~~~~^~~~
  File "C:\Users\sumit\BotKapil\Lib\site-packages\pandas\core\ops\common.py", line 76, in new_method
    return method(self, other)
  File "C:\Users\sumit\BotKapil\Lib\site-packages\pandas\core\arraylike.py", line 186, in __add__
    return self._arith_method(other, operator.add)
           ~~~~~~~~~~~~~~~~~~^^^^^^^^^^^^^^^^^^^^^
  File "C:\Users\sumit\BotKapil\Lib\site-packages\pandas\core\series.py", line 6135, in _arith_method
    return base.IndexOpsMixin._arith_method(self, other, op)
           ~~~~~~~~~~~~~~~~~~~~~~~~~~~~~~~~^^^^^^^^^^^^^^^^^
  File "C:\Users\sumit\BotKapil\Lib\site-packages\pandas\core\base.py", line 1382, in _arith_method
    result = ops.arithmetic_op(lvalues, rvalues, op)
  File "C:\Users\sumit\BotKapil\Lib\site-packages\pandas\core\ops\array_ops.py", line 273, in arithmetic_op
    res_values = op(left, right)
TypeError: unsupported operand type(s) for +: 'DatetimeArray' and 'str'
06-04-25 19:06:42 - ERROR - unsupported operand type(s) for +: 'Timestamp' and 'str'
Traceback (most recent call last):
  File "C:\Users\sumit\BotKapil\BotKapil\utility\utility.py", line 132, in gettestdata
    df['updated_at']=df['updated_at']+df['Time']
                     ~~~~~~~~~~~~~~~~^~~~~~~~~~~
  File "C:\Users\sumit\BotKapil\Lib\site-packages\pandas\core\ops\common.py", line 76, in new_method
    return method(self, other)
  File "C:\Users\sumit\BotKapil\Lib\site-packages\pandas\core\arraylike.py", line 186, in __add__
    return self._arith_method(other, operator.add)
           ~~~~~~~~~~~~~~~~~~^^^^^^^^^^^^^^^^^^^^^
  File "C:\Users\sumit\BotKapil\Lib\site-packages\pandas\core\series.py", line 6135, in _arith_method
    return base.IndexOpsMixin._arith_method(self, other, op)
           ~~~~~~~~~~~~~~~~~~~~~~~~~~~~~~~~^^^^^^^^^^^^^^^^^
  File "C:\Users\sumit\BotKapil\Lib\site-packages\pandas\core\base.py", line 1382, in _arith_method
    result = ops.arithmetic_op(lvalues, rvalues, op)
  File "C:\Users\sumit\BotKapil\Lib\site-packages\pandas\core\ops\array_ops.py", line 273, in arithmetic_op
    res_values = op(left, right)
  File "C:\Users\sumit\BotKapil\Lib\site-packages\pandas\core\ops\common.py", line 76, in new_method
    return method(self, other)
  File "C:\Users\sumit\BotKapil\Lib\site-packages\pandas\core\arrays\datetimelike.py", line 1393, in __add__
    result = self._addsub_object_array(other, operator.add)
  File "C:\Users\sumit\BotKapil\Lib\site-packages\pandas\core\arrays\datetimelike.py", line 1350, in _addsub_object_array
    res_values = op(self.astype("O"), np.asarray(other))
TypeError: unsupported operand type(s) for +: 'Timestamp' and 'str'
07-04-25 14:41:07 - ERROR - 'module' object is not callable
07-04-25 14:41:51 - ERROR - 'module' object is not callable
07-04-25 14:42:21 - ERROR - 'module' object is not callable
07-04-25 14:42:23 - ERROR - 'module' object is not callable
07-04-25 14:46:49 - ERROR - 'module' object is not callable
07-04-25 14:46:51 - ERROR - 'module' object is not callable
07-04-25 14:54:22 - ERROR - 'module' object is not callable
07-04-25 14:54:23 - ERROR - 'module' object is not callable
07-04-25 14:58:08 - ERROR - 'module' object is not callable
07-04-25 14:58:10 - ERROR - 'module' object is not callable
07-04-25 15:00:12 - ERROR - 'module' object is not callable
07-04-25 15:00:14 - ERROR - 'module' object is not callable
07-04-25 15:01:07 - ERROR - 'module' object is not callable
07-04-25 15:01:08 - ERROR - 'module' object is not callable
07-04-25 15:01:44 - ERROR - 'module' object is not callable
07-04-25 15:01:45 - ERROR - 'module' object is not callable
07-04-25 15:01:46 - ERROR - check the orderobject function The truth value of a DataFrame is ambiguous. Use a.empty, a.bool(), a.item(), a.any() or a.all().
07-04-25 15:02:52 - ERROR - 'module' object is not callable
07-04-25 15:02:54 - ERROR - 'module' object is not callable
07-04-25 15:02:55 - ERROR - check the orderobject function The truth value of a DataFrame is ambiguous. Use a.empty, a.bool(), a.item(), a.any() or a.all().
07-04-25 15:05:00 - ERROR - check the orderobject function 'list' object has no attribute 'empty'
07-04-25 15:05:00 - ERROR - 'module' object is not callable
07-04-25 15:05:01 - ERROR - check the orderobject function 'list' object has no attribute 'empty'
07-04-25 15:05:01 - ERROR - 'module' object is not callable
07-04-25 15:05:01 - ERROR - check the orderobject function 'list' object has no attribute 'empty'
07-04-25 15:05:02 - ERROR - check the orderobject function 'list' object has no attribute 'empty'
07-04-25 15:06:31 - ERROR - 'module' object is not callable
07-04-25 15:06:32 - ERROR - 'module' object is not callable
07-04-25 15:06:33 - ERROR - check the orderobject function cannot access local variable 'file' where it is not associated with a value
07-04-25 15:14:18 - ERROR - 'module' object is not callable
07-04-25 15:14:19 - ERROR - 'module' object is not callable
07-04-25 15:15:49 - ERROR - 'module' object is not callable
07-04-25 15:15:50 - ERROR - 'module' object is not callable
07-04-25 15:17:27 - ERROR - 'module' object is not callable
07-04-25 15:17:28 - ERROR - 'module' object is not callable
07-04-25 15:19:42 - ERROR - 'module' object is not callable
07-04-25 15:19:44 - ERROR - 'module' object is not callable
07-04-25 15:19:45 - ERROR - check the orderobject function [Errno 13] Permission denied: 'C:\\Users\\sumit\\BotKapil\\BotKapil\\data/liveorderdata/orderdata.csv'
07-04-25 15:25:39 - ERROR - 'module' object is not callable
07-04-25 15:25:41 - ERROR - 'module' object is not callable
07-04-25 15:25:42 - ERROR - check the orderobject function [Errno 13] Permission denied: 'C:\\Users\\sumit\\BotKapil\\BotKapil\\data/liveorderdata/orderdata.csv'
07-04-25 15:27:14 - ERROR - 'module' object is not callable
07-04-25 15:27:16 - ERROR - 'module' object is not callable
07-04-25 15:27:17 - ERROR - check the orderobject function cannot access local variable 'file' where it is not associated with a value
07-04-25 15:32:12 - ERROR - 'module' object is not callable
07-04-25 15:32:13 - ERROR - 'module' object is not callable
07-04-25 15:32:14 - ERROR - check the orderobject function [Errno 13] Permission denied: 'C:\\Users\\sumit\\BotKapil\\BotKapil\\data/liveorderdata/orderdata.csv'
07-04-25 15:32:40 - ERROR - 'module' object is not callable
07-04-25 15:32:41 - ERROR - 'module' object is not callable
07-04-25 15:32:42 - ERROR - check the orderobject function cannot access local variable 'file' where it is not associated with a value
08-04-25 00:54:43 - ERROR - 'module' object is not callable
08-04-25 00:55:42 - ERROR - 'module' object is not callable
08-04-25 01:01:33 - ERROR - 'module' object is not callable
08-04-25 01:06:27 - ERROR - 'module' object is not callable
08-04-25 01:08:13 - ERROR - 'module' object is not callable
08-04-25 01:10:49 - ERROR - 'module' object is not callable
08-04-25 01:11:55 - ERROR - 'module' object is not callable
08-04-25 01:11:55 - ERROR - 'module' object is not callable
08-04-25 01:14:19 - ERROR - 'module' object is not callable
08-04-25 01:14:20 - ERROR - 'module' object is not callable
08-04-25 01:27:00 - ERROR - 'module' object is not callable
08-04-25 01:27:01 - ERROR - 'module' object is not callable
08-04-25 01:46:10 - ERROR - 'module' object is not callable
08-04-25 01:46:11 - ERROR - 'module' object is not callable
08-04-25 01:48:57 - ERROR - 'module' object is not callable
08-04-25 01:49:18 - ERROR - 'module' object is not callable
08-04-25 01:49:19 - ERROR - 'module' object is not callable
08-04-25 01:50:42 - ERROR - 'module' object is not callable
08-04-25 01:50:43 - ERROR - 'module' object is not callable
08-04-25 01:52:00 - ERROR - 'module' object is not callable
08-04-25 01:52:00 - ERROR - 'module' object is not callable
08-04-25 01:59:54 - ERROR - 'module' object is not callable
08-04-25 01:59:55 - ERROR - "None of ['updated_at'] are in the columns"
Traceback (most recent call last):
  File "C:\Users\sumit\BotKapil\BotKapil\utility\utility.py", line 190, in buildcandels
    df = data.set_index('updated_at')
  File "C:\Users\sumit\BotKapil\Lib\site-packages\pandas\core\frame.py", line 6122, in set_index
    raise KeyError(f"None of {missing} are in the columns")
KeyError: "None of ['updated_at'] are in the columns"
08-04-25 01:59:55 - ERROR - 'module' object is not callable
08-04-25 02:00:22 - ERROR - 'module' object is not callable
08-04-25 02:00:22 - ERROR - "None of ['updated_at'] are in the columns"
Traceback (most recent call last):
  File "C:\Users\sumit\BotKapil\BotKapil\utility\utility.py", line 190, in buildcandels
    df = data.set_index('updated_at')
  File "C:\Users\sumit\BotKapil\Lib\site-packages\pandas\core\frame.py", line 6122, in set_index
    raise KeyError(f"None of {missing} are in the columns")
KeyError: "None of ['updated_at'] are in the columns"
08-04-25 02:00:22 - ERROR - 'module' object is not callable
08-04-25 02:02:24 - ERROR - 'module' object is not callable
08-04-25 02:02:25 - ERROR - 'module' object is not callable
08-04-25 15:26:37 - ERROR - 'module' object is not callable
08-04-25 15:26:38 - ERROR - 'status'
Traceback (most recent call last):
  File "C:\Users\sumit\BotKapil\Lib\site-packages\pandas\core\indexes\base.py", line 3805, in get_loc
    return self._engine.get_loc(casted_key)
           ~~~~~~~~~~~~~~~~~~~~^^^^^^^^^^^^
  File "index.pyx", line 167, in pandas._libs.index.IndexEngine.get_loc
  File "index.pyx", line 196, in pandas._libs.index.IndexEngine.get_loc
  File "pandas\\_libs\\hashtable_class_helper.pxi", line 7081, in pandas._libs.hashtable.PyObjectHashTable.get_item
  File "pandas\\_libs\\hashtable_class_helper.pxi", line 7089, in pandas._libs.hashtable.PyObjectHashTable.get_item
KeyError: 'status'

The above exception was the direct cause of the following exception:

Traceback (most recent call last):
  File "C:\Users\sumit\BotKapil\BotKapil\utility\utility.py", line 101, in closeorder
    orderobj= orderobj[orderobj['status']==1]
                       ~~~~~~~~^^^^^^^^^^
  File "C:\Users\sumit\BotKapil\Lib\site-packages\pandas\core\frame.py", line 4102, in __getitem__
    indexer = self.columns.get_loc(key)
  File "C:\Users\sumit\BotKapil\Lib\site-packages\pandas\core\indexes\base.py", line 3812, in get_loc
    raise KeyError(key) from err
KeyError: 'status'
08-04-25 15:27:43 - ERROR - 'module' object is not callable
08-04-25 15:27:44 - ERROR - 'status'
Traceback (most recent call last):
  File "C:\Users\sumit\BotKapil\Lib\site-packages\pandas\core\indexes\base.py", line 3805, in get_loc
    return self._engine.get_loc(casted_key)
           ~~~~~~~~~~~~~~~~~~~~^^^^^^^^^^^^
  File "index.pyx", line 167, in pandas._libs.index.IndexEngine.get_loc
  File "index.pyx", line 196, in pandas._libs.index.IndexEngine.get_loc
  File "pandas\\_libs\\hashtable_class_helper.pxi", line 7081, in pandas._libs.hashtable.PyObjectHashTable.get_item
  File "pandas\\_libs\\hashtable_class_helper.pxi", line 7089, in pandas._libs.hashtable.PyObjectHashTable.get_item
KeyError: 'status'

The above exception was the direct cause of the following exception:

Traceback (most recent call last):
  File "C:\Users\sumit\BotKapil\BotKapil\utility\utility.py", line 101, in closeorder
    orderobj= orderobj[orderobj['status']==1]
                       ~~~~~~~~^^^^^^^^^^
  File "C:\Users\sumit\BotKapil\Lib\site-packages\pandas\core\frame.py", line 4102, in __getitem__
    indexer = self.columns.get_loc(key)
  File "C:\Users\sumit\BotKapil\Lib\site-packages\pandas\core\indexes\base.py", line 3812, in get_loc
    raise KeyError(key) from err
KeyError: 'status'
08-04-25 15:29:46 - ERROR - 'module' object is not callable
08-04-25 15:29:46 - ERROR - 'Backtest'
Traceback (most recent call last):
  File "C:\Users\sumit\BotKapil\Lib\site-packages\pandas\core\indexes\base.py", line 3805, in get_loc
    return self._engine.get_loc(casted_key)
           ~~~~~~~~~~~~~~~~~~~~^^^^^^^^^^^^
  File "index.pyx", line 167, in pandas._libs.index.IndexEngine.get_loc
  File "index.pyx", line 196, in pandas._libs.index.IndexEngine.get_loc
  File "pandas\\_libs\\hashtable_class_helper.pxi", line 7081, in pandas._libs.hashtable.PyObjectHashTable.get_item
  File "pandas\\_libs\\hashtable_class_helper.pxi", line 7089, in pandas._libs.hashtable.PyObjectHashTable.get_item
KeyError: 'Backtest'

The above exception was the direct cause of the following exception:

Traceback (most recent call last):
  File "C:\Users\sumit\BotKapil\BotKapil\utility\utility.py", line 104, in closeorder
    if (orderobj['Slhit'].iloc[i] or     orderobj['Slhit'].iloc[i] or orderobj['Slhit'].iloc[i]) and not orderobj['Backtest'].iloc[i]  :
                                                                                                         ~~~~~~~~^^^^^^^^^^^^
  File "C:\Users\sumit\BotKapil\Lib\site-packages\pandas\core\frame.py", line 4102, in __getitem__
    indexer = self.columns.get_loc(key)
  File "C:\Users\sumit\BotKapil\Lib\site-packages\pandas\core\indexes\base.py", line 3812, in get_loc
    raise KeyError(key) from err
KeyError: 'Backtest'
08-04-25 15:31:09 - ERROR - 'module' object is not callable
08-04-25 15:31:09 - ERROR - 'module' object is not callable
08-04-25 15:32:17 - ERROR - 'module' object is not callable
08-04-25 15:32:18 - ERROR - 'module' object is not callable
08-04-25 15:34:56 - ERROR - 'module' object is not callable
08-04-25 15:34:56 - ERROR - 'module' object is not callable
08-04-25 15:34:57 - ERROR - 'target'
Traceback (most recent call last):
  File "C:\Users\sumit\BotKapil\BotKapil\utility\utility.py", line 153, in processorder
    order_ids=broker.placeorder(orderparams,self.orderobject,True)
  File "C:\Users\sumit\BotKapil\BotKapil\Broker\Angelsdk.py", line 364, in placeorder
    orderupdate.loc[-1,'Target']=orderparam['target']
                                 ~~~~~~~~~~^^^^^^^^^^
KeyError: 'target'
08-04-25 15:37:11 - ERROR - 'module' object is not callable
08-04-25 15:37:11 - ERROR - 'module' object is not callable
08-04-25 15:42:46 - ERROR - 'module' object is not callable
08-04-25 15:42:46 - ERROR - 'module' object is not callable
08-04-25 15:46:55 - ERROR - 'module' object is not callable
08-04-25 15:46:55 - ERROR - 'module' object is not callable
08-04-25 15:51:51 - ERROR - 'module' object is not callable
08-04-25 15:51:51 - ERROR - 'module' object is not callable
08-04-25 15:54:09 - ERROR - 'module' object is not callable
08-04-25 15:54:09 - ERROR - 'module' object is not callable
08-04-25 15:56:23 - ERROR - 'module' object is not callable
Traceback (most recent call last):
  File "C:\Users\sumit\BotKapil\BotKapil\utility\utility.py", line 183, in fetchaccounts
    logpath= os.path(path,logpath)
TypeError: 'module' object is not callable
08-04-25 15:56:23 - ERROR - 'module' object is not callable
Traceback (most recent call last):
  File "C:\Users\sumit\BotKapil\BotKapil\utility\utility.py", line 183, in fetchaccounts
    logpath= os.path(path,logpath)
TypeError: 'module' object is not callable
08-04-25 15:57:37 - ERROR - [Errno 2] No such file or directory: 'C:\\Users\\sumit\\BotKapil\\BotKapilconfig/account.csv'
Traceback (most recent call last):
  File "C:\Users\sumit\BotKapil\BotKapil\utility\utility.py", line 189, in fetchaccounts
    df= pd.read_csv(path+f"config/account.csv")
  File "C:\Users\sumit\BotKapil\Lib\site-packages\pandas\io\parsers\readers.py", line 1026, in read_csv
    return _read(filepath_or_buffer, kwds)
  File "C:\Users\sumit\BotKapil\Lib\site-packages\pandas\io\parsers\readers.py", line 620, in _read
    parser = TextFileReader(filepath_or_buffer, **kwds)
  File "C:\Users\sumit\BotKapil\Lib\site-packages\pandas\io\parsers\readers.py", line 1620, in __init__
    self._engine = self._make_engine(f, self.engine)
                   ~~~~~~~~~~~~~~~~~^^^^^^^^^^^^^^^^
  File "C:\Users\sumit\BotKapil\Lib\site-packages\pandas\io\parsers\readers.py", line 1880, in _make_engine
    self.handles = get_handle(
                   ~~~~~~~~~~^
        f,
        ^^
    ...<6 lines>...
        storage_options=self.options.get("storage_options", None),
        ^^^^^^^^^^^^^^^^^^^^^^^^^^^^^^^^^^^^^^^^^^^^^^^^^^^^^^^^^^
    )
    ^
  File "C:\Users\sumit\BotKapil\Lib\site-packages\pandas\io\common.py", line 873, in get_handle
    handle = open(
        handle,
    ...<3 lines>...
        newline="",
    )
FileNotFoundError: [Errno 2] No such file or directory: 'C:\\Users\\sumit\\BotKapil\\BotKapilconfig/account.csv'
08-04-25 15:57:37 - ERROR - [Errno 2] No such file or directory: 'C:\\Users\\sumit\\BotKapil\\BotKapilconfig/account.csv'
Traceback (most recent call last):
  File "C:\Users\sumit\BotKapil\BotKapil\utility\utility.py", line 189, in fetchaccounts
    df= pd.read_csv(path+f"config/account.csv")
  File "C:\Users\sumit\BotKapil\Lib\site-packages\pandas\io\parsers\readers.py", line 1026, in read_csv
    return _read(filepath_or_buffer, kwds)
  File "C:\Users\sumit\BotKapil\Lib\site-packages\pandas\io\parsers\readers.py", line 620, in _read
    parser = TextFileReader(filepath_or_buffer, **kwds)
  File "C:\Users\sumit\BotKapil\Lib\site-packages\pandas\io\parsers\readers.py", line 1620, in __init__
    self._engine = self._make_engine(f, self.engine)
                   ~~~~~~~~~~~~~~~~~^^^^^^^^^^^^^^^^
  File "C:\Users\sumit\BotKapil\Lib\site-packages\pandas\io\parsers\readers.py", line 1880, in _make_engine
    self.handles = get_handle(
                   ~~~~~~~~~~^
        f,
        ^^
    ...<6 lines>...
        storage_options=self.options.get("storage_options", None),
        ^^^^^^^^^^^^^^^^^^^^^^^^^^^^^^^^^^^^^^^^^^^^^^^^^^^^^^^^^^
    )
    ^
  File "C:\Users\sumit\BotKapil\Lib\site-packages\pandas\io\common.py", line 873, in get_handle
    handle = open(
        handle,
    ...<3 lines>...
        newline="",
    )
FileNotFoundError: [Errno 2] No such file or directory: 'C:\\Users\\sumit\\BotKapil\\BotKapilconfig/account.csv'
08-04-25 15:59:51 - ERROR - No columns to parse from file
Traceback (most recent call last):
  File "C:\Users\sumit\BotKapil\BotKapil\utility\utility.py", line 189, in fetchaccounts
    df= pd.read_csv(logpath)
  File "C:\Users\sumit\BotKapil\Lib\site-packages\pandas\io\parsers\readers.py", line 1026, in read_csv
    return _read(filepath_or_buffer, kwds)
  File "C:\Users\sumit\BotKapil\Lib\site-packages\pandas\io\parsers\readers.py", line 620, in _read
    parser = TextFileReader(filepath_or_buffer, **kwds)
  File "C:\Users\sumit\BotKapil\Lib\site-packages\pandas\io\parsers\readers.py", line 1620, in __init__
    self._engine = self._make_engine(f, self.engine)
                   ~~~~~~~~~~~~~~~~~^^^^^^^^^^^^^^^^
  File "C:\Users\sumit\BotKapil\Lib\site-packages\pandas\io\parsers\readers.py", line 1898, in _make_engine
    return mapping[engine](f, **self.options)
           ~~~~~~~~~~~~~~~^^^^^^^^^^^^^^^^^^^
  File "C:\Users\sumit\BotKapil\Lib\site-packages\pandas\io\parsers\c_parser_wrapper.py", line 93, in __init__
    self._reader = parsers.TextReader(src, **kwds)
                   ~~~~~~~~~~~~~~~~~~^^^^^^^^^^^^^
  File "parsers.pyx", line 581, in pandas._libs.parsers.TextReader.__cinit__
pandas.errors.EmptyDataError: No columns to parse from file
08-04-25 15:59:51 - ERROR - No columns to parse from file
Traceback (most recent call last):
  File "C:\Users\sumit\BotKapil\BotKapil\utility\utility.py", line 189, in fetchaccounts
    df= pd.read_csv(logpath)
  File "C:\Users\sumit\BotKapil\Lib\site-packages\pandas\io\parsers\readers.py", line 1026, in read_csv
    return _read(filepath_or_buffer, kwds)
  File "C:\Users\sumit\BotKapil\Lib\site-packages\pandas\io\parsers\readers.py", line 620, in _read
    parser = TextFileReader(filepath_or_buffer, **kwds)
  File "C:\Users\sumit\BotKapil\Lib\site-packages\pandas\io\parsers\readers.py", line 1620, in __init__
    self._engine = self._make_engine(f, self.engine)
                   ~~~~~~~~~~~~~~~~~^^^^^^^^^^^^^^^^
  File "C:\Users\sumit\BotKapil\Lib\site-packages\pandas\io\parsers\readers.py", line 1898, in _make_engine
    return mapping[engine](f, **self.options)
           ~~~~~~~~~~~~~~~^^^^^^^^^^^^^^^^^^^
  File "C:\Users\sumit\BotKapil\Lib\site-packages\pandas\io\parsers\c_parser_wrapper.py", line 93, in __init__
    self._reader = parsers.TextReader(src, **kwds)
                   ~~~~~~~~~~~~~~~~~~^^^^^^^^^^^^^
  File "parsers.pyx", line 581, in pandas._libs.parsers.TextReader.__cinit__
pandas.errors.EmptyDataError: No columns to parse from file
08-04-25 16:03:39 - ERROR - No columns to parse from file
Traceback (most recent call last):
  File "C:\Users\sumit\BotKapil\BotKapil\utility\utility.py", line 189, in fetchaccounts
    df= pd.read_csv(logpath)
  File "C:\Users\sumit\BotKapil\Lib\site-packages\pandas\io\parsers\readers.py", line 1026, in read_csv
    return _read(filepath_or_buffer, kwds)
  File "C:\Users\sumit\BotKapil\Lib\site-packages\pandas\io\parsers\readers.py", line 620, in _read
    parser = TextFileReader(filepath_or_buffer, **kwds)
  File "C:\Users\sumit\BotKapil\Lib\site-packages\pandas\io\parsers\readers.py", line 1620, in __init__
    self._engine = self._make_engine(f, self.engine)
                   ~~~~~~~~~~~~~~~~~^^^^^^^^^^^^^^^^
  File "C:\Users\sumit\BotKapil\Lib\site-packages\pandas\io\parsers\readers.py", line 1898, in _make_engine
    return mapping[engine](f, **self.options)
           ~~~~~~~~~~~~~~~^^^^^^^^^^^^^^^^^^^
  File "C:\Users\sumit\BotKapil\Lib\site-packages\pandas\io\parsers\c_parser_wrapper.py", line 93, in __init__
    self._reader = parsers.TextReader(src, **kwds)
                   ~~~~~~~~~~~~~~~~~~^^^^^^^^^^^^^
  File "parsers.pyx", line 581, in pandas._libs.parsers.TextReader.__cinit__
pandas.errors.EmptyDataError: No columns to parse from file
08-04-25 16:03:39 - ERROR - No columns to parse from file
Traceback (most recent call last):
  File "C:\Users\sumit\BotKapil\BotKapil\utility\utility.py", line 189, in fetchaccounts
    df= pd.read_csv(logpath)
  File "C:\Users\sumit\BotKapil\Lib\site-packages\pandas\io\parsers\readers.py", line 1026, in read_csv
    return _read(filepath_or_buffer, kwds)
  File "C:\Users\sumit\BotKapil\Lib\site-packages\pandas\io\parsers\readers.py", line 620, in _read
    parser = TextFileReader(filepath_or_buffer, **kwds)
  File "C:\Users\sumit\BotKapil\Lib\site-packages\pandas\io\parsers\readers.py", line 1620, in __init__
    self._engine = self._make_engine(f, self.engine)
                   ~~~~~~~~~~~~~~~~~^^^^^^^^^^^^^^^^
  File "C:\Users\sumit\BotKapil\Lib\site-packages\pandas\io\parsers\readers.py", line 1898, in _make_engine
    return mapping[engine](f, **self.options)
           ~~~~~~~~~~~~~~~^^^^^^^^^^^^^^^^^^^
  File "C:\Users\sumit\BotKapil\Lib\site-packages\pandas\io\parsers\c_parser_wrapper.py", line 93, in __init__
    self._reader = parsers.TextReader(src, **kwds)
                   ~~~~~~~~~~~~~~~~~~^^^^^^^^^^^^^
  File "parsers.pyx", line 581, in pandas._libs.parsers.TextReader.__cinit__
pandas.errors.EmptyDataError: No columns to parse from file
08-04-25 16:07:41 - ERROR - check the orderobject function cannot access local variable 'file' where it is not associated with a value
08-04-25 23:47:06 - ERROR - check the orderobject function cannot access local variable 'file' where it is not associated with a value
08-04-25 23:55:12 - ERROR - Cannot convert non-finite values (NA or inf) to integer
Traceback (most recent call last):
  File "C:\Users\sumit\BotKapil\BotKapil\utility\utility.py", line 104, in closeorder
    orderobj=pd.DataFrame(orderobj,dtype='int8')
  File "C:\Users\sumit\BotKapil\Lib\site-packages\pandas\core\frame.py", line 772, in __init__
    mgr = self._init_mgr(
        data, axes={"index": index, "columns": columns}, dtype=dtype, copy=copy
    )
  File "C:\Users\sumit\BotKapil\Lib\site-packages\pandas\core\generic.py", line 313, in _init_mgr
    mgr = mgr.astype(dtype=dtype)
  File "C:\Users\sumit\BotKapil\Lib\site-packages\pandas\core\internals\managers.py", line 430, in astype
    return self.apply(
           ~~~~~~~~~~^
        "astype",
        ^^^^^^^^^
    ...<3 lines>...
        using_cow=using_copy_on_write(),
        ^^^^^^^^^^^^^^^^^^^^^^^^^^^^^^^^
    )
    ^
  File "C:\Users\sumit\BotKapil\Lib\site-packages\pandas\core\internals\managers.py", line 363, in apply
    applied = getattr(b, f)(**kwargs)
  File "C:\Users\sumit\BotKapil\Lib\site-packages\pandas\core\internals\blocks.py", line 758, in astype
    new_values = astype_array_safe(values, dtype, copy=copy, errors=errors)
  File "C:\Users\sumit\BotKapil\Lib\site-packages\pandas\core\dtypes\astype.py", line 237, in astype_array_safe
    new_values = astype_array(values, dtype, copy=copy)
  File "C:\Users\sumit\BotKapil\Lib\site-packages\pandas\core\dtypes\astype.py", line 182, in astype_array
    values = _astype_nansafe(values, dtype, copy=copy)
  File "C:\Users\sumit\BotKapil\Lib\site-packages\pandas\core\dtypes\astype.py", line 101, in _astype_nansafe
    return _astype_float_to_int_nansafe(arr, dtype, copy)
  File "C:\Users\sumit\BotKapil\Lib\site-packages\pandas\core\dtypes\astype.py", line 145, in _astype_float_to_int_nansafe
    raise IntCastingNaNError(
        "Cannot convert non-finite values (NA or inf) to integer"
    )
pandas.errors.IntCastingNaNError: Cannot convert non-finite values (NA or inf) to integer
09-04-25 00:21:36 - INFO - Check order close
09-04-25 00:23:36 - INFO - Check order close
09-04-25 00:32:29 - ERROR - check the orderobject function [Errno 13] Permission denied: 'C:\\Users\\sumit\\BotKapil\\BotKapil\\data/liveorderdata/orderdata.csv'
09-04-25 00:32:30 - ERROR - check the orderobject function [Errno 13] Permission denied: 'C:\\Users\\sumit\\BotKapil\\BotKapil\\data/liveorderdata/orderdata.csv'
09-04-25 00:32:31 - ERROR - check the orderobject function [Errno 13] Permission denied: 'C:\\Users\\sumit\\BotKapil\\BotKapil\\data/liveorderdata/orderdata.csv'
09-04-25 00:32:31 - ERROR - Couldn't parse the JSON response received from the server: b'Access denied because of exceeding access rate'
Traceback (most recent call last):
  File "C:\Users\sumit\BotKapil\BotKapil\Broker\SmartApi\smartConnect.py", line 230, in _request
    data = json.loads(r.content.decode("utf8"))
  File "C:\Users\sumit\AppData\Local\Programs\Python\Python313\Lib\json\__init__.py", line 346, in loads
    return _default_decoder.decode(s)
           ~~~~~~~~~~~~~~~~~~~~~~~^^^
  File "C:\Users\sumit\AppData\Local\Programs\Python\Python313\Lib\json\decoder.py", line 345, in decode
    obj, end = self.raw_decode(s, idx=_w(s, 0).end())
               ~~~~~~~~~~~~~~~^^^^^^^^^^^^^^^^^^^^^^^
  File "C:\Users\sumit\AppData\Local\Programs\Python\Python313\Lib\json\decoder.py", line 363, in raw_decode
    raise JSONDecodeError("Expecting value", s, err.value) from None
json.decoder.JSONDecodeError: Expecting value: line 1 column 1 (char 0)

During handling of the above exception, another exception occurred:

Traceback (most recent call last):
  File "C:\Users\sumit\BotKapil\BotKapil\utility\utility.py", line 156, in processorder
    broker= Angel.HTTP(1)
  File "C:\Users\sumit\BotKapil\BotKapil\Broker\Angelsdk.py", line 171, in __init__
    super().__init__(self,api_key , username ,pwd,token)
    ~~~~~~~~~~~~~~~~^^^^^^^^^^^^^^^^^^^^^^^^^^^^^^^^^^^^
  File "C:\Users\sumit\BotKapil\BotKapil\Broker\Angelsdk.py", line 120, in __init__
    self.smartAPI_Login()
    ~~~~~~~~~~~~~~~~~~~^^
  File "C:\Users\sumit\BotKapil\BotKapil\Broker\Angelsdk.py", line 131, in smartAPI_Login
    data = self.smartApi.generateSession(self.username, self.pwd, totp)
  File "C:\Users\sumit\BotKapil\BotKapil\Broker\SmartApi\smartConnect.py", line 271, in generateSession
    loginResultObject=self._postRequest("api.login",params)
  File "C:\Users\sumit\BotKapil\BotKapil\Broker\SmartApi\smartConnect.py", line 263, in _postRequest
    return self._request(route, "POST", params)
           ~~~~~~~~~~~~~^^^^^^^^^^^^^^^^^^^^^^^
  File "C:\Users\sumit\BotKapil\BotKapil\Broker\SmartApi\smartConnect.py", line 233, in _request
    raise ex.DataException("Couldn't parse the JSON response received from the server: {content}".format(
        content=r.content))
BotKapil.Broker.SmartApi.smartExceptions.DataException: Couldn't parse the JSON response received from the server: b'Access denied because of exceeding access rate'
09-04-25 00:32:32 - ERROR - check the orderobject function [Errno 13] Permission denied: 'C:\\Users\\sumit\\BotKapil\\BotKapil\\data/liveorderdata/orderdata.csv'
09-04-25 00:32:32 - ERROR - Couldn't parse the JSON response received from the server: b'Access denied because of exceeding access rate'
Traceback (most recent call last):
  File "C:\Users\sumit\BotKapil\BotKapil\Broker\SmartApi\smartConnect.py", line 230, in _request
    data = json.loads(r.content.decode("utf8"))
  File "C:\Users\sumit\AppData\Local\Programs\Python\Python313\Lib\json\__init__.py", line 346, in loads
    return _default_decoder.decode(s)
           ~~~~~~~~~~~~~~~~~~~~~~~^^^
  File "C:\Users\sumit\AppData\Local\Programs\Python\Python313\Lib\json\decoder.py", line 345, in decode
    obj, end = self.raw_decode(s, idx=_w(s, 0).end())
               ~~~~~~~~~~~~~~~^^^^^^^^^^^^^^^^^^^^^^^
  File "C:\Users\sumit\AppData\Local\Programs\Python\Python313\Lib\json\decoder.py", line 363, in raw_decode
    raise JSONDecodeError("Expecting value", s, err.value) from None
json.decoder.JSONDecodeError: Expecting value: line 1 column 1 (char 0)

During handling of the above exception, another exception occurred:

Traceback (most recent call last):
  File "C:\Users\sumit\BotKapil\BotKapil\utility\utility.py", line 156, in processorder
    broker= Angel.HTTP(1)
  File "C:\Users\sumit\BotKapil\BotKapil\Broker\Angelsdk.py", line 171, in __init__
    super().__init__(self,api_key , username ,pwd,token)
    ~~~~~~~~~~~~~~~~^^^^^^^^^^^^^^^^^^^^^^^^^^^^^^^^^^^^
  File "C:\Users\sumit\BotKapil\BotKapil\Broker\Angelsdk.py", line 120, in __init__
    self.smartAPI_Login()
    ~~~~~~~~~~~~~~~~~~~^^
  File "C:\Users\sumit\BotKapil\BotKapil\Broker\Angelsdk.py", line 131, in smartAPI_Login
    data = self.smartApi.generateSession(self.username, self.pwd, totp)
  File "C:\Users\sumit\BotKapil\BotKapil\Broker\SmartApi\smartConnect.py", line 271, in generateSession
    loginResultObject=self._postRequest("api.login",params)
  File "C:\Users\sumit\BotKapil\BotKapil\Broker\SmartApi\smartConnect.py", line 263, in _postRequest
    return self._request(route, "POST", params)
           ~~~~~~~~~~~~~^^^^^^^^^^^^^^^^^^^^^^^
  File "C:\Users\sumit\BotKapil\BotKapil\Broker\SmartApi\smartConnect.py", line 233, in _request
    raise ex.DataException("Couldn't parse the JSON response received from the server: {content}".format(
        content=r.content))
BotKapil.Broker.SmartApi.smartExceptions.DataException: Couldn't parse the JSON response received from the server: b'Access denied because of exceeding access rate'
09-04-25 00:32:32 - ERROR - Couldn't parse the JSON response received from the server: b'Access denied because of exceeding access rate'
Traceback (most recent call last):
  File "C:\Users\sumit\BotKapil\BotKapil\Broker\SmartApi\smartConnect.py", line 230, in _request
    data = json.loads(r.content.decode("utf8"))
  File "C:\Users\sumit\AppData\Local\Programs\Python\Python313\Lib\json\__init__.py", line 346, in loads
    return _default_decoder.decode(s)
           ~~~~~~~~~~~~~~~~~~~~~~~^^^
  File "C:\Users\sumit\AppData\Local\Programs\Python\Python313\Lib\json\decoder.py", line 345, in decode
    obj, end = self.raw_decode(s, idx=_w(s, 0).end())
               ~~~~~~~~~~~~~~~^^^^^^^^^^^^^^^^^^^^^^^
  File "C:\Users\sumit\AppData\Local\Programs\Python\Python313\Lib\json\decoder.py", line 363, in raw_decode
    raise JSONDecodeError("Expecting value", s, err.value) from None
json.decoder.JSONDecodeError: Expecting value: line 1 column 1 (char 0)

During handling of the above exception, another exception occurred:

Traceback (most recent call last):
  File "C:\Users\sumit\BotKapil\BotKapil\utility\utility.py", line 156, in processorder
    broker= Angel.HTTP(1)
  File "C:\Users\sumit\BotKapil\BotKapil\Broker\Angelsdk.py", line 171, in __init__
    super().__init__(self,api_key , username ,pwd,token)
    ~~~~~~~~~~~~~~~~^^^^^^^^^^^^^^^^^^^^^^^^^^^^^^^^^^^^
  File "C:\Users\sumit\BotKapil\BotKapil\Broker\Angelsdk.py", line 120, in __init__
    self.smartAPI_Login()
    ~~~~~~~~~~~~~~~~~~~^^
  File "C:\Users\sumit\BotKapil\BotKapil\Broker\Angelsdk.py", line 131, in smartAPI_Login
    data = self.smartApi.generateSession(self.username, self.pwd, totp)
  File "C:\Users\sumit\BotKapil\BotKapil\Broker\SmartApi\smartConnect.py", line 271, in generateSession
    loginResultObject=self._postRequest("api.login",params)
  File "C:\Users\sumit\BotKapil\BotKapil\Broker\SmartApi\smartConnect.py", line 263, in _postRequest
    return self._request(route, "POST", params)
           ~~~~~~~~~~~~~^^^^^^^^^^^^^^^^^^^^^^^
  File "C:\Users\sumit\BotKapil\BotKapil\Broker\SmartApi\smartConnect.py", line 233, in _request
    raise ex.DataException("Couldn't parse the JSON response received from the server: {content}".format(
        content=r.content))
BotKapil.Broker.SmartApi.smartExceptions.DataException: Couldn't parse the JSON response received from the server: b'Access denied because of exceeding access rate'
09-04-25 00:32:32 - ERROR - Couldn't parse the JSON response received from the server: b'Access denied because of exceeding access rate'
Traceback (most recent call last):
  File "C:\Users\sumit\BotKapil\BotKapil\Broker\SmartApi\smartConnect.py", line 230, in _request
    data = json.loads(r.content.decode("utf8"))
  File "C:\Users\sumit\AppData\Local\Programs\Python\Python313\Lib\json\__init__.py", line 346, in loads
    return _default_decoder.decode(s)
           ~~~~~~~~~~~~~~~~~~~~~~~^^^
  File "C:\Users\sumit\AppData\Local\Programs\Python\Python313\Lib\json\decoder.py", line 345, in decode
    obj, end = self.raw_decode(s, idx=_w(s, 0).end())
               ~~~~~~~~~~~~~~~^^^^^^^^^^^^^^^^^^^^^^^
  File "C:\Users\sumit\AppData\Local\Programs\Python\Python313\Lib\json\decoder.py", line 363, in raw_decode
    raise JSONDecodeError("Expecting value", s, err.value) from None
json.decoder.JSONDecodeError: Expecting value: line 1 column 1 (char 0)

During handling of the above exception, another exception occurred:

Traceback (most recent call last):
  File "C:\Users\sumit\BotKapil\BotKapil\utility\utility.py", line 156, in processorder
    broker= Angel.HTTP(1)
  File "C:\Users\sumit\BotKapil\BotKapil\Broker\Angelsdk.py", line 171, in __init__
    super().__init__(self,api_key , username ,pwd,token)
    ~~~~~~~~~~~~~~~~^^^^^^^^^^^^^^^^^^^^^^^^^^^^^^^^^^^^
  File "C:\Users\sumit\BotKapil\BotKapil\Broker\Angelsdk.py", line 120, in __init__
    self.smartAPI_Login()
    ~~~~~~~~~~~~~~~~~~~^^
  File "C:\Users\sumit\BotKapil\BotKapil\Broker\Angelsdk.py", line 131, in smartAPI_Login
    data = self.smartApi.generateSession(self.username, self.pwd, totp)
  File "C:\Users\sumit\BotKapil\BotKapil\Broker\SmartApi\smartConnect.py", line 271, in generateSession
    loginResultObject=self._postRequest("api.login",params)
  File "C:\Users\sumit\BotKapil\BotKapil\Broker\SmartApi\smartConnect.py", line 263, in _postRequest
    return self._request(route, "POST", params)
           ~~~~~~~~~~~~~^^^^^^^^^^^^^^^^^^^^^^^
  File "C:\Users\sumit\BotKapil\BotKapil\Broker\SmartApi\smartConnect.py", line 233, in _request
    raise ex.DataException("Couldn't parse the JSON response received from the server: {content}".format(
        content=r.content))
BotKapil.Broker.SmartApi.smartExceptions.DataException: Couldn't parse the JSON response received from the server: b'Access denied because of exceeding access rate'
09-04-25 00:32:32 - ERROR - Couldn't parse the JSON response received from the server: b'Access denied because of exceeding access rate'
Traceback (most recent call last):
  File "C:\Users\sumit\BotKapil\BotKapil\Broker\SmartApi\smartConnect.py", line 230, in _request
    data = json.loads(r.content.decode("utf8"))
  File "C:\Users\sumit\AppData\Local\Programs\Python\Python313\Lib\json\__init__.py", line 346, in loads
    return _default_decoder.decode(s)
           ~~~~~~~~~~~~~~~~~~~~~~~^^^
  File "C:\Users\sumit\AppData\Local\Programs\Python\Python313\Lib\json\decoder.py", line 345, in decode
    obj, end = self.raw_decode(s, idx=_w(s, 0).end())
               ~~~~~~~~~~~~~~~^^^^^^^^^^^^^^^^^^^^^^^
  File "C:\Users\sumit\AppData\Local\Programs\Python\Python313\Lib\json\decoder.py", line 363, in raw_decode
    raise JSONDecodeError("Expecting value", s, err.value) from None
json.decoder.JSONDecodeError: Expecting value: line 1 column 1 (char 0)

During handling of the above exception, another exception occurred:

Traceback (most recent call last):
  File "C:\Users\sumit\BotKapil\BotKapil\utility\utility.py", line 156, in processorder
    broker= Angel.HTTP(1)
  File "C:\Users\sumit\BotKapil\BotKapil\Broker\Angelsdk.py", line 171, in __init__
    super().__init__(self,api_key , username ,pwd,token)
    ~~~~~~~~~~~~~~~~^^^^^^^^^^^^^^^^^^^^^^^^^^^^^^^^^^^^
  File "C:\Users\sumit\BotKapil\BotKapil\Broker\Angelsdk.py", line 120, in __init__
    self.smartAPI_Login()
    ~~~~~~~~~~~~~~~~~~~^^
  File "C:\Users\sumit\BotKapil\BotKapil\Broker\Angelsdk.py", line 131, in smartAPI_Login
    data = self.smartApi.generateSession(self.username, self.pwd, totp)
  File "C:\Users\sumit\BotKapil\BotKapil\Broker\SmartApi\smartConnect.py", line 271, in generateSession
    loginResultObject=self._postRequest("api.login",params)
  File "C:\Users\sumit\BotKapil\BotKapil\Broker\SmartApi\smartConnect.py", line 263, in _postRequest
    return self._request(route, "POST", params)
           ~~~~~~~~~~~~~^^^^^^^^^^^^^^^^^^^^^^^
  File "C:\Users\sumit\BotKapil\BotKapil\Broker\SmartApi\smartConnect.py", line 233, in _request
    raise ex.DataException("Couldn't parse the JSON response received from the server: {content}".format(
        content=r.content))
BotKapil.Broker.SmartApi.smartExceptions.DataException: Couldn't parse the JSON response received from the server: b'Access denied because of exceeding access rate'
09-04-25 00:32:33 - ERROR - check the orderobject function [Errno 13] Permission denied: 'C:\\Users\\sumit\\BotKapil\\BotKapil\\data/liveorderdata/orderdata.csv'
09-04-25 00:40:12 - ERROR - Couldn't parse the JSON response received from the server: b'Access denied because of exceeding access rate'
Traceback (most recent call last):
  File "C:\Users\sumit\BotKapil\BotKapil\Broker\SmartApi\smartConnect.py", line 230, in _request
    data = json.loads(r.content.decode("utf8"))
  File "C:\Users\sumit\AppData\Local\Programs\Python\Python313\Lib\json\__init__.py", line 346, in loads
    return _default_decoder.decode(s)
           ~~~~~~~~~~~~~~~~~~~~~~~^^^
  File "C:\Users\sumit\AppData\Local\Programs\Python\Python313\Lib\json\decoder.py", line 345, in decode
    obj, end = self.raw_decode(s, idx=_w(s, 0).end())
               ~~~~~~~~~~~~~~~^^^^^^^^^^^^^^^^^^^^^^^
  File "C:\Users\sumit\AppData\Local\Programs\Python\Python313\Lib\json\decoder.py", line 363, in raw_decode
    raise JSONDecodeError("Expecting value", s, err.value) from None
json.decoder.JSONDecodeError: Expecting value: line 1 column 1 (char 0)

During handling of the above exception, another exception occurred:

Traceback (most recent call last):
  File "C:\Users\sumit\BotKapil\BotKapil\utility\utility.py", line 156, in processorder
    broker= Angel.HTTP(1)
  File "C:\Users\sumit\BotKapil\BotKapil\Broker\Angelsdk.py", line 171, in __init__
    super().__init__(self,api_key , username ,pwd,token)
    ~~~~~~~~~~~~~~~~^^^^^^^^^^^^^^^^^^^^^^^^^^^^^^^^^^^^
  File "C:\Users\sumit\BotKapil\BotKapil\Broker\Angelsdk.py", line 120, in __init__
    self.smartAPI_Login()
    ~~~~~~~~~~~~~~~~~~~^^
  File "C:\Users\sumit\BotKapil\BotKapil\Broker\Angelsdk.py", line 131, in smartAPI_Login
    data = self.smartApi.generateSession(self.username, self.pwd, totp)
  File "C:\Users\sumit\BotKapil\BotKapil\Broker\SmartApi\smartConnect.py", line 271, in generateSession
    loginResultObject=self._postRequest("api.login",params)
  File "C:\Users\sumit\BotKapil\BotKapil\Broker\SmartApi\smartConnect.py", line 263, in _postRequest
    return self._request(route, "POST", params)
           ~~~~~~~~~~~~~^^^^^^^^^^^^^^^^^^^^^^^
  File "C:\Users\sumit\BotKapil\BotKapil\Broker\SmartApi\smartConnect.py", line 233, in _request
    raise ex.DataException("Couldn't parse the JSON response received from the server: {content}".format(
        content=r.content))
BotKapil.Broker.SmartApi.smartExceptions.DataException: Couldn't parse the JSON response received from the server: b'Access denied because of exceeding access rate'
09-04-25 00:40:12 - ERROR - Couldn't parse the JSON response received from the server: b'Access denied because of exceeding access rate'
Traceback (most recent call last):
  File "C:\Users\sumit\BotKapil\BotKapil\Broker\SmartApi\smartConnect.py", line 230, in _request
    data = json.loads(r.content.decode("utf8"))
  File "C:\Users\sumit\AppData\Local\Programs\Python\Python313\Lib\json\__init__.py", line 346, in loads
    return _default_decoder.decode(s)
           ~~~~~~~~~~~~~~~~~~~~~~~^^^
  File "C:\Users\sumit\AppData\Local\Programs\Python\Python313\Lib\json\decoder.py", line 345, in decode
    obj, end = self.raw_decode(s, idx=_w(s, 0).end())
               ~~~~~~~~~~~~~~~^^^^^^^^^^^^^^^^^^^^^^^
  File "C:\Users\sumit\AppData\Local\Programs\Python\Python313\Lib\json\decoder.py", line 363, in raw_decode
    raise JSONDecodeError("Expecting value", s, err.value) from None
json.decoder.JSONDecodeError: Expecting value: line 1 column 1 (char 0)

During handling of the above exception, another exception occurred:

Traceback (most recent call last):
  File "C:\Users\sumit\BotKapil\BotKapil\utility\utility.py", line 156, in processorder
    broker= Angel.HTTP(1)
  File "C:\Users\sumit\BotKapil\BotKapil\Broker\Angelsdk.py", line 171, in __init__
    super().__init__(self,api_key , username ,pwd,token)
    ~~~~~~~~~~~~~~~~^^^^^^^^^^^^^^^^^^^^^^^^^^^^^^^^^^^^
  File "C:\Users\sumit\BotKapil\BotKapil\Broker\Angelsdk.py", line 120, in __init__
    self.smartAPI_Login()
    ~~~~~~~~~~~~~~~~~~~^^
  File "C:\Users\sumit\BotKapil\BotKapil\Broker\Angelsdk.py", line 131, in smartAPI_Login
    data = self.smartApi.generateSession(self.username, self.pwd, totp)
  File "C:\Users\sumit\BotKapil\BotKapil\Broker\SmartApi\smartConnect.py", line 271, in generateSession
    loginResultObject=self._postRequest("api.login",params)
  File "C:\Users\sumit\BotKapil\BotKapil\Broker\SmartApi\smartConnect.py", line 263, in _postRequest
    return self._request(route, "POST", params)
           ~~~~~~~~~~~~~^^^^^^^^^^^^^^^^^^^^^^^
  File "C:\Users\sumit\BotKapil\BotKapil\Broker\SmartApi\smartConnect.py", line 233, in _request
    raise ex.DataException("Couldn't parse the JSON response received from the server: {content}".format(
        content=r.content))
BotKapil.Broker.SmartApi.smartExceptions.DataException: Couldn't parse the JSON response received from the server: b'Access denied because of exceeding access rate'
09-04-25 00:40:12 - ERROR - Couldn't parse the JSON response received from the server: b'Access denied because of exceeding access rate'
Traceback (most recent call last):
  File "C:\Users\sumit\BotKapil\BotKapil\Broker\SmartApi\smartConnect.py", line 230, in _request
    data = json.loads(r.content.decode("utf8"))
  File "C:\Users\sumit\AppData\Local\Programs\Python\Python313\Lib\json\__init__.py", line 346, in loads
    return _default_decoder.decode(s)
           ~~~~~~~~~~~~~~~~~~~~~~~^^^
  File "C:\Users\sumit\AppData\Local\Programs\Python\Python313\Lib\json\decoder.py", line 345, in decode
    obj, end = self.raw_decode(s, idx=_w(s, 0).end())
               ~~~~~~~~~~~~~~~^^^^^^^^^^^^^^^^^^^^^^^
  File "C:\Users\sumit\AppData\Local\Programs\Python\Python313\Lib\json\decoder.py", line 363, in raw_decode
    raise JSONDecodeError("Expecting value", s, err.value) from None
json.decoder.JSONDecodeError: Expecting value: line 1 column 1 (char 0)

During handling of the above exception, another exception occurred:

Traceback (most recent call last):
  File "C:\Users\sumit\BotKapil\BotKapil\utility\utility.py", line 156, in processorder
    broker= Angel.HTTP(1)
  File "C:\Users\sumit\BotKapil\BotKapil\Broker\Angelsdk.py", line 171, in __init__
    super().__init__(self,api_key , username ,pwd,token)
    ~~~~~~~~~~~~~~~~^^^^^^^^^^^^^^^^^^^^^^^^^^^^^^^^^^^^
  File "C:\Users\sumit\BotKapil\BotKapil\Broker\Angelsdk.py", line 120, in __init__
    self.smartAPI_Login()
    ~~~~~~~~~~~~~~~~~~~^^
  File "C:\Users\sumit\BotKapil\BotKapil\Broker\Angelsdk.py", line 131, in smartAPI_Login
    data = self.smartApi.generateSession(self.username, self.pwd, totp)
  File "C:\Users\sumit\BotKapil\BotKapil\Broker\SmartApi\smartConnect.py", line 271, in generateSession
    loginResultObject=self._postRequest("api.login",params)
  File "C:\Users\sumit\BotKapil\BotKapil\Broker\SmartApi\smartConnect.py", line 263, in _postRequest
    return self._request(route, "POST", params)
           ~~~~~~~~~~~~~^^^^^^^^^^^^^^^^^^^^^^^
  File "C:\Users\sumit\BotKapil\BotKapil\Broker\SmartApi\smartConnect.py", line 233, in _request
    raise ex.DataException("Couldn't parse the JSON response received from the server: {content}".format(
        content=r.content))
BotKapil.Broker.SmartApi.smartExceptions.DataException: Couldn't parse the JSON response received from the server: b'Access denied because of exceeding access rate'
09-04-25 00:40:12 - ERROR - Couldn't parse the JSON response received from the server: b'Access denied because of exceeding access rate'
Traceback (most recent call last):
  File "C:\Users\sumit\BotKapil\BotKapil\Broker\SmartApi\smartConnect.py", line 230, in _request
    data = json.loads(r.content.decode("utf8"))
  File "C:\Users\sumit\AppData\Local\Programs\Python\Python313\Lib\json\__init__.py", line 346, in loads
    return _default_decoder.decode(s)
           ~~~~~~~~~~~~~~~~~~~~~~~^^^
  File "C:\Users\sumit\AppData\Local\Programs\Python\Python313\Lib\json\decoder.py", line 345, in decode
    obj, end = self.raw_decode(s, idx=_w(s, 0).end())
               ~~~~~~~~~~~~~~~^^^^^^^^^^^^^^^^^^^^^^^
  File "C:\Users\sumit\AppData\Local\Programs\Python\Python313\Lib\json\decoder.py", line 363, in raw_decode
    raise JSONDecodeError("Expecting value", s, err.value) from None
json.decoder.JSONDecodeError: Expecting value: line 1 column 1 (char 0)

During handling of the above exception, another exception occurred:

Traceback (most recent call last):
  File "C:\Users\sumit\BotKapil\BotKapil\utility\utility.py", line 156, in processorder
    broker= Angel.HTTP(1)
  File "C:\Users\sumit\BotKapil\BotKapil\Broker\Angelsdk.py", line 171, in __init__
    super().__init__(self,api_key , username ,pwd,token)
    ~~~~~~~~~~~~~~~~^^^^^^^^^^^^^^^^^^^^^^^^^^^^^^^^^^^^
  File "C:\Users\sumit\BotKapil\BotKapil\Broker\Angelsdk.py", line 120, in __init__
    self.smartAPI_Login()
    ~~~~~~~~~~~~~~~~~~~^^
  File "C:\Users\sumit\BotKapil\BotKapil\Broker\Angelsdk.py", line 131, in smartAPI_Login
    data = self.smartApi.generateSession(self.username, self.pwd, totp)
  File "C:\Users\sumit\BotKapil\BotKapil\Broker\SmartApi\smartConnect.py", line 271, in generateSession
    loginResultObject=self._postRequest("api.login",params)
  File "C:\Users\sumit\BotKapil\BotKapil\Broker\SmartApi\smartConnect.py", line 263, in _postRequest
    return self._request(route, "POST", params)
           ~~~~~~~~~~~~~^^^^^^^^^^^^^^^^^^^^^^^
  File "C:\Users\sumit\BotKapil\BotKapil\Broker\SmartApi\smartConnect.py", line 233, in _request
    raise ex.DataException("Couldn't parse the JSON response received from the server: {content}".format(
        content=r.content))
BotKapil.Broker.SmartApi.smartExceptions.DataException: Couldn't parse the JSON response received from the server: b'Access denied because of exceeding access rate'
09-04-25 00:41:52 - ERROR - Couldn't parse the JSON response received from the server: b'Access denied because of exceeding access rate'
Traceback (most recent call last):
  File "C:\Users\sumit\BotKapil\BotKapil\Broker\SmartApi\smartConnect.py", line 230, in _request
    data = json.loads(r.content.decode("utf8"))
  File "C:\Users\sumit\AppData\Local\Programs\Python\Python313\Lib\json\__init__.py", line 346, in loads
    return _default_decoder.decode(s)
           ~~~~~~~~~~~~~~~~~~~~~~~^^^
  File "C:\Users\sumit\AppData\Local\Programs\Python\Python313\Lib\json\decoder.py", line 345, in decode
    obj, end = self.raw_decode(s, idx=_w(s, 0).end())
               ~~~~~~~~~~~~~~~^^^^^^^^^^^^^^^^^^^^^^^
  File "C:\Users\sumit\AppData\Local\Programs\Python\Python313\Lib\json\decoder.py", line 363, in raw_decode
    raise JSONDecodeError("Expecting value", s, err.value) from None
json.decoder.JSONDecodeError: Expecting value: line 1 column 1 (char 0)

During handling of the above exception, another exception occurred:

Traceback (most recent call last):
  File "C:\Users\sumit\BotKapil\BotKapil\utility\utility.py", line 156, in processorder
    broker= Angel.HTTP(1)
  File "C:\Users\sumit\BotKapil\BotKapil\Broker\Angelsdk.py", line 171, in __init__
    super().__init__(self,api_key , username ,pwd,token)
    ~~~~~~~~~~~~~~~~^^^^^^^^^^^^^^^^^^^^^^^^^^^^^^^^^^^^
  File "C:\Users\sumit\BotKapil\BotKapil\Broker\Angelsdk.py", line 120, in __init__
    self.smartAPI_Login()
    ~~~~~~~~~~~~~~~~~~~^^
  File "C:\Users\sumit\BotKapil\BotKapil\Broker\Angelsdk.py", line 131, in smartAPI_Login
    data = self.smartApi.generateSession(self.username, self.pwd, totp)
  File "C:\Users\sumit\BotKapil\BotKapil\Broker\SmartApi\smartConnect.py", line 271, in generateSession
    loginResultObject=self._postRequest("api.login",params)
  File "C:\Users\sumit\BotKapil\BotKapil\Broker\SmartApi\smartConnect.py", line 263, in _postRequest
    return self._request(route, "POST", params)
           ~~~~~~~~~~~~~^^^^^^^^^^^^^^^^^^^^^^^
  File "C:\Users\sumit\BotKapil\BotKapil\Broker\SmartApi\smartConnect.py", line 233, in _request
    raise ex.DataException("Couldn't parse the JSON response received from the server: {content}".format(
        content=r.content))
BotKapil.Broker.SmartApi.smartExceptions.DataException: Couldn't parse the JSON response received from the server: b'Access denied because of exceeding access rate'
09-04-25 00:41:52 - ERROR - Couldn't parse the JSON response received from the server: b'Access denied because of exceeding access rate'
Traceback (most recent call last):
  File "C:\Users\sumit\BotKapil\BotKapil\Broker\SmartApi\smartConnect.py", line 230, in _request
    data = json.loads(r.content.decode("utf8"))
  File "C:\Users\sumit\AppData\Local\Programs\Python\Python313\Lib\json\__init__.py", line 346, in loads
    return _default_decoder.decode(s)
           ~~~~~~~~~~~~~~~~~~~~~~~^^^
  File "C:\Users\sumit\AppData\Local\Programs\Python\Python313\Lib\json\decoder.py", line 345, in decode
    obj, end = self.raw_decode(s, idx=_w(s, 0).end())
               ~~~~~~~~~~~~~~~^^^^^^^^^^^^^^^^^^^^^^^
  File "C:\Users\sumit\AppData\Local\Programs\Python\Python313\Lib\json\decoder.py", line 363, in raw_decode
    raise JSONDecodeError("Expecting value", s, err.value) from None
json.decoder.JSONDecodeError: Expecting value: line 1 column 1 (char 0)

During handling of the above exception, another exception occurred:

Traceback (most recent call last):
  File "C:\Users\sumit\BotKapil\BotKapil\utility\utility.py", line 156, in processorder
    broker= Angel.HTTP(1)
  File "C:\Users\sumit\BotKapil\BotKapil\Broker\Angelsdk.py", line 171, in __init__
    super().__init__(self,api_key , username ,pwd,token)
    ~~~~~~~~~~~~~~~~^^^^^^^^^^^^^^^^^^^^^^^^^^^^^^^^^^^^
  File "C:\Users\sumit\BotKapil\BotKapil\Broker\Angelsdk.py", line 120, in __init__
    self.smartAPI_Login()
    ~~~~~~~~~~~~~~~~~~~^^
  File "C:\Users\sumit\BotKapil\BotKapil\Broker\Angelsdk.py", line 131, in smartAPI_Login
    data = self.smartApi.generateSession(self.username, self.pwd, totp)
  File "C:\Users\sumit\BotKapil\BotKapil\Broker\SmartApi\smartConnect.py", line 271, in generateSession
    loginResultObject=self._postRequest("api.login",params)
  File "C:\Users\sumit\BotKapil\BotKapil\Broker\SmartApi\smartConnect.py", line 263, in _postRequest
    return self._request(route, "POST", params)
           ~~~~~~~~~~~~~^^^^^^^^^^^^^^^^^^^^^^^
  File "C:\Users\sumit\BotKapil\BotKapil\Broker\SmartApi\smartConnect.py", line 233, in _request
    raise ex.DataException("Couldn't parse the JSON response received from the server: {content}".format(
        content=r.content))
BotKapil.Broker.SmartApi.smartExceptions.DataException: Couldn't parse the JSON response received from the server: b'Access denied because of exceeding access rate'
09-04-25 00:41:52 - ERROR - Couldn't parse the JSON response received from the server: b'Access denied because of exceeding access rate'
Traceback (most recent call last):
  File "C:\Users\sumit\BotKapil\BotKapil\Broker\SmartApi\smartConnect.py", line 230, in _request
    data = json.loads(r.content.decode("utf8"))
  File "C:\Users\sumit\AppData\Local\Programs\Python\Python313\Lib\json\__init__.py", line 346, in loads
    return _default_decoder.decode(s)
           ~~~~~~~~~~~~~~~~~~~~~~~^^^
  File "C:\Users\sumit\AppData\Local\Programs\Python\Python313\Lib\json\decoder.py", line 345, in decode
    obj, end = self.raw_decode(s, idx=_w(s, 0).end())
               ~~~~~~~~~~~~~~~^^^^^^^^^^^^^^^^^^^^^^^
  File "C:\Users\sumit\AppData\Local\Programs\Python\Python313\Lib\json\decoder.py", line 363, in raw_decode
    raise JSONDecodeError("Expecting value", s, err.value) from None
json.decoder.JSONDecodeError: Expecting value: line 1 column 1 (char 0)

During handling of the above exception, another exception occurred:

Traceback (most recent call last):
  File "C:\Users\sumit\BotKapil\BotKapil\utility\utility.py", line 156, in processorder
    broker= Angel.HTTP(1)
  File "C:\Users\sumit\BotKapil\BotKapil\Broker\Angelsdk.py", line 171, in __init__
    super().__init__(self,api_key , username ,pwd,token)
    ~~~~~~~~~~~~~~~~^^^^^^^^^^^^^^^^^^^^^^^^^^^^^^^^^^^^
  File "C:\Users\sumit\BotKapil\BotKapil\Broker\Angelsdk.py", line 120, in __init__
    self.smartAPI_Login()
    ~~~~~~~~~~~~~~~~~~~^^
  File "C:\Users\sumit\BotKapil\BotKapil\Broker\Angelsdk.py", line 131, in smartAPI_Login
    data = self.smartApi.generateSession(self.username, self.pwd, totp)
  File "C:\Users\sumit\BotKapil\BotKapil\Broker\SmartApi\smartConnect.py", line 271, in generateSession
    loginResultObject=self._postRequest("api.login",params)
  File "C:\Users\sumit\BotKapil\BotKapil\Broker\SmartApi\smartConnect.py", line 263, in _postRequest
    return self._request(route, "POST", params)
           ~~~~~~~~~~~~~^^^^^^^^^^^^^^^^^^^^^^^
  File "C:\Users\sumit\BotKapil\BotKapil\Broker\SmartApi\smartConnect.py", line 233, in _request
    raise ex.DataException("Couldn't parse the JSON response received from the server: {content}".format(
        content=r.content))
BotKapil.Broker.SmartApi.smartExceptions.DataException: Couldn't parse the JSON response received from the server: b'Access denied because of exceeding access rate'
09-04-25 00:41:52 - ERROR - Couldn't parse the JSON response received from the server: b'Access denied because of exceeding access rate'
Traceback (most recent call last):
  File "C:\Users\sumit\BotKapil\BotKapil\Broker\SmartApi\smartConnect.py", line 230, in _request
    data = json.loads(r.content.decode("utf8"))
  File "C:\Users\sumit\AppData\Local\Programs\Python\Python313\Lib\json\__init__.py", line 346, in loads
    return _default_decoder.decode(s)
           ~~~~~~~~~~~~~~~~~~~~~~~^^^
  File "C:\Users\sumit\AppData\Local\Programs\Python\Python313\Lib\json\decoder.py", line 345, in decode
    obj, end = self.raw_decode(s, idx=_w(s, 0).end())
               ~~~~~~~~~~~~~~~^^^^^^^^^^^^^^^^^^^^^^^
  File "C:\Users\sumit\AppData\Local\Programs\Python\Python313\Lib\json\decoder.py", line 363, in raw_decode
    raise JSONDecodeError("Expecting value", s, err.value) from None
json.decoder.JSONDecodeError: Expecting value: line 1 column 1 (char 0)

During handling of the above exception, another exception occurred:

Traceback (most recent call last):
  File "C:\Users\sumit\BotKapil\BotKapil\utility\utility.py", line 156, in processorder
    broker= Angel.HTTP(1)
  File "C:\Users\sumit\BotKapil\BotKapil\Broker\Angelsdk.py", line 171, in __init__
    super().__init__(self,api_key , username ,pwd,token)
    ~~~~~~~~~~~~~~~~^^^^^^^^^^^^^^^^^^^^^^^^^^^^^^^^^^^^
  File "C:\Users\sumit\BotKapil\BotKapil\Broker\Angelsdk.py", line 120, in __init__
    self.smartAPI_Login()
    ~~~~~~~~~~~~~~~~~~~^^
  File "C:\Users\sumit\BotKapil\BotKapil\Broker\Angelsdk.py", line 131, in smartAPI_Login
    data = self.smartApi.generateSession(self.username, self.pwd, totp)
  File "C:\Users\sumit\BotKapil\BotKapil\Broker\SmartApi\smartConnect.py", line 271, in generateSession
    loginResultObject=self._postRequest("api.login",params)
  File "C:\Users\sumit\BotKapil\BotKapil\Broker\SmartApi\smartConnect.py", line 263, in _postRequest
    return self._request(route, "POST", params)
           ~~~~~~~~~~~~~^^^^^^^^^^^^^^^^^^^^^^^
  File "C:\Users\sumit\BotKapil\BotKapil\Broker\SmartApi\smartConnect.py", line 233, in _request
    raise ex.DataException("Couldn't parse the JSON response received from the server: {content}".format(
        content=r.content))
BotKapil.Broker.SmartApi.smartExceptions.DataException: Couldn't parse the JSON response received from the server: b'Access denied because of exceeding access rate'
09-04-25 00:45:14 - ERROR - Couldn't parse the JSON response received from the server: b'Access denied because of exceeding access rate'
Traceback (most recent call last):
  File "C:\Users\sumit\BotKapil\BotKapil\Broker\SmartApi\smartConnect.py", line 230, in _request
    data = json.loads(r.content.decode("utf8"))
  File "C:\Users\sumit\AppData\Local\Programs\Python\Python313\Lib\json\__init__.py", line 346, in loads
    return _default_decoder.decode(s)
           ~~~~~~~~~~~~~~~~~~~~~~~^^^
  File "C:\Users\sumit\AppData\Local\Programs\Python\Python313\Lib\json\decoder.py", line 345, in decode
    obj, end = self.raw_decode(s, idx=_w(s, 0).end())
               ~~~~~~~~~~~~~~~^^^^^^^^^^^^^^^^^^^^^^^
  File "C:\Users\sumit\AppData\Local\Programs\Python\Python313\Lib\json\decoder.py", line 363, in raw_decode
    raise JSONDecodeError("Expecting value", s, err.value) from None
json.decoder.JSONDecodeError: Expecting value: line 1 column 1 (char 0)

During handling of the above exception, another exception occurred:

Traceback (most recent call last):
  File "C:\Users\sumit\BotKapil\BotKapil\utility\utility.py", line 156, in processorder
    broker= Angel.HTTP(1)
  File "C:\Users\sumit\BotKapil\BotKapil\Broker\Angelsdk.py", line 171, in __init__
    super().__init__(self,api_key , username ,pwd,token)
    ~~~~~~~~~~~~~~~~^^^^^^^^^^^^^^^^^^^^^^^^^^^^^^^^^^^^
  File "C:\Users\sumit\BotKapil\BotKapil\Broker\Angelsdk.py", line 120, in __init__
    self.smartAPI_Login()
    ~~~~~~~~~~~~~~~~~~~^^
  File "C:\Users\sumit\BotKapil\BotKapil\Broker\Angelsdk.py", line 131, in smartAPI_Login
    data = self.smartApi.generateSession(self.username, self.pwd, totp)
  File "C:\Users\sumit\BotKapil\BotKapil\Broker\SmartApi\smartConnect.py", line 271, in generateSession
    loginResultObject=self._postRequest("api.login",params)
  File "C:\Users\sumit\BotKapil\BotKapil\Broker\SmartApi\smartConnect.py", line 263, in _postRequest
    return self._request(route, "POST", params)
           ~~~~~~~~~~~~~^^^^^^^^^^^^^^^^^^^^^^^
  File "C:\Users\sumit\BotKapil\BotKapil\Broker\SmartApi\smartConnect.py", line 233, in _request
    raise ex.DataException("Couldn't parse the JSON response received from the server: {content}".format(
        content=r.content))
BotKapil.Broker.SmartApi.smartExceptions.DataException: Couldn't parse the JSON response received from the server: b'Access denied because of exceeding access rate'
09-04-25 00:45:14 - ERROR - Couldn't parse the JSON response received from the server: b'Access denied because of exceeding access rate'
Traceback (most recent call last):
  File "C:\Users\sumit\BotKapil\BotKapil\Broker\SmartApi\smartConnect.py", line 230, in _request
    data = json.loads(r.content.decode("utf8"))
  File "C:\Users\sumit\AppData\Local\Programs\Python\Python313\Lib\json\__init__.py", line 346, in loads
    return _default_decoder.decode(s)
           ~~~~~~~~~~~~~~~~~~~~~~~^^^
  File "C:\Users\sumit\AppData\Local\Programs\Python\Python313\Lib\json\decoder.py", line 345, in decode
    obj, end = self.raw_decode(s, idx=_w(s, 0).end())
               ~~~~~~~~~~~~~~~^^^^^^^^^^^^^^^^^^^^^^^
  File "C:\Users\sumit\AppData\Local\Programs\Python\Python313\Lib\json\decoder.py", line 363, in raw_decode
    raise JSONDecodeError("Expecting value", s, err.value) from None
json.decoder.JSONDecodeError: Expecting value: line 1 column 1 (char 0)

During handling of the above exception, another exception occurred:

Traceback (most recent call last):
  File "C:\Users\sumit\BotKapil\BotKapil\utility\utility.py", line 156, in processorder
    broker= Angel.HTTP(1)
  File "C:\Users\sumit\BotKapil\BotKapil\Broker\Angelsdk.py", line 171, in __init__
    super().__init__(self,api_key , username ,pwd,token)
    ~~~~~~~~~~~~~~~~^^^^^^^^^^^^^^^^^^^^^^^^^^^^^^^^^^^^
  File "C:\Users\sumit\BotKapil\BotKapil\Broker\Angelsdk.py", line 120, in __init__
    self.smartAPI_Login()
    ~~~~~~~~~~~~~~~~~~~^^
  File "C:\Users\sumit\BotKapil\BotKapil\Broker\Angelsdk.py", line 131, in smartAPI_Login
    data = self.smartApi.generateSession(self.username, self.pwd, totp)
  File "C:\Users\sumit\BotKapil\BotKapil\Broker\SmartApi\smartConnect.py", line 271, in generateSession
    loginResultObject=self._postRequest("api.login",params)
  File "C:\Users\sumit\BotKapil\BotKapil\Broker\SmartApi\smartConnect.py", line 263, in _postRequest
    return self._request(route, "POST", params)
           ~~~~~~~~~~~~~^^^^^^^^^^^^^^^^^^^^^^^
  File "C:\Users\sumit\BotKapil\BotKapil\Broker\SmartApi\smartConnect.py", line 233, in _request
    raise ex.DataException("Couldn't parse the JSON response received from the server: {content}".format(
        content=r.content))
BotKapil.Broker.SmartApi.smartExceptions.DataException: Couldn't parse the JSON response received from the server: b'Access denied because of exceeding access rate'
09-04-25 00:45:14 - ERROR - Couldn't parse the JSON response received from the server: b'Access denied because of exceeding access rate'
Traceback (most recent call last):
  File "C:\Users\sumit\BotKapil\BotKapil\Broker\SmartApi\smartConnect.py", line 230, in _request
    data = json.loads(r.content.decode("utf8"))
  File "C:\Users\sumit\AppData\Local\Programs\Python\Python313\Lib\json\__init__.py", line 346, in loads
    return _default_decoder.decode(s)
           ~~~~~~~~~~~~~~~~~~~~~~~^^^
  File "C:\Users\sumit\AppData\Local\Programs\Python\Python313\Lib\json\decoder.py", line 345, in decode
    obj, end = self.raw_decode(s, idx=_w(s, 0).end())
               ~~~~~~~~~~~~~~~^^^^^^^^^^^^^^^^^^^^^^^
  File "C:\Users\sumit\AppData\Local\Programs\Python\Python313\Lib\json\decoder.py", line 363, in raw_decode
    raise JSONDecodeError("Expecting value", s, err.value) from None
json.decoder.JSONDecodeError: Expecting value: line 1 column 1 (char 0)

During handling of the above exception, another exception occurred:

Traceback (most recent call last):
  File "C:\Users\sumit\BotKapil\BotKapil\utility\utility.py", line 156, in processorder
    broker= Angel.HTTP(1)
  File "C:\Users\sumit\BotKapil\BotKapil\Broker\Angelsdk.py", line 171, in __init__
    super().__init__(self,api_key , username ,pwd,token)
    ~~~~~~~~~~~~~~~~^^^^^^^^^^^^^^^^^^^^^^^^^^^^^^^^^^^^
  File "C:\Users\sumit\BotKapil\BotKapil\Broker\Angelsdk.py", line 120, in __init__
    self.smartAPI_Login()
    ~~~~~~~~~~~~~~~~~~~^^
  File "C:\Users\sumit\BotKapil\BotKapil\Broker\Angelsdk.py", line 131, in smartAPI_Login
    data = self.smartApi.generateSession(self.username, self.pwd, totp)
  File "C:\Users\sumit\BotKapil\BotKapil\Broker\SmartApi\smartConnect.py", line 271, in generateSession
    loginResultObject=self._postRequest("api.login",params)
  File "C:\Users\sumit\BotKapil\BotKapil\Broker\SmartApi\smartConnect.py", line 263, in _postRequest
    return self._request(route, "POST", params)
           ~~~~~~~~~~~~~^^^^^^^^^^^^^^^^^^^^^^^
  File "C:\Users\sumit\BotKapil\BotKapil\Broker\SmartApi\smartConnect.py", line 233, in _request
    raise ex.DataException("Couldn't parse the JSON response received from the server: {content}".format(
        content=r.content))
BotKapil.Broker.SmartApi.smartExceptions.DataException: Couldn't parse the JSON response received from the server: b'Access denied because of exceeding access rate'
09-04-25 00:45:14 - ERROR - Couldn't parse the JSON response received from the server: b'Access denied because of exceeding access rate'
Traceback (most recent call last):
  File "C:\Users\sumit\BotKapil\BotKapil\Broker\SmartApi\smartConnect.py", line 230, in _request
    data = json.loads(r.content.decode("utf8"))
  File "C:\Users\sumit\AppData\Local\Programs\Python\Python313\Lib\json\__init__.py", line 346, in loads
    return _default_decoder.decode(s)
           ~~~~~~~~~~~~~~~~~~~~~~~^^^
  File "C:\Users\sumit\AppData\Local\Programs\Python\Python313\Lib\json\decoder.py", line 345, in decode
    obj, end = self.raw_decode(s, idx=_w(s, 0).end())
               ~~~~~~~~~~~~~~~^^^^^^^^^^^^^^^^^^^^^^^
  File "C:\Users\sumit\AppData\Local\Programs\Python\Python313\Lib\json\decoder.py", line 363, in raw_decode
    raise JSONDecodeError("Expecting value", s, err.value) from None
json.decoder.JSONDecodeError: Expecting value: line 1 column 1 (char 0)

During handling of the above exception, another exception occurred:

Traceback (most recent call last):
  File "C:\Users\sumit\BotKapil\BotKapil\utility\utility.py", line 156, in processorder
    broker= Angel.HTTP(1)
  File "C:\Users\sumit\BotKapil\BotKapil\Broker\Angelsdk.py", line 171, in __init__
    super().__init__(self,api_key , username ,pwd,token)
    ~~~~~~~~~~~~~~~~^^^^^^^^^^^^^^^^^^^^^^^^^^^^^^^^^^^^
  File "C:\Users\sumit\BotKapil\BotKapil\Broker\Angelsdk.py", line 120, in __init__
    self.smartAPI_Login()
    ~~~~~~~~~~~~~~~~~~~^^
  File "C:\Users\sumit\BotKapil\BotKapil\Broker\Angelsdk.py", line 131, in smartAPI_Login
    data = self.smartApi.generateSession(self.username, self.pwd, totp)
  File "C:\Users\sumit\BotKapil\BotKapil\Broker\SmartApi\smartConnect.py", line 271, in generateSession
    loginResultObject=self._postRequest("api.login",params)
  File "C:\Users\sumit\BotKapil\BotKapil\Broker\SmartApi\smartConnect.py", line 263, in _postRequest
    return self._request(route, "POST", params)
           ~~~~~~~~~~~~~^^^^^^^^^^^^^^^^^^^^^^^
  File "C:\Users\sumit\BotKapil\BotKapil\Broker\SmartApi\smartConnect.py", line 233, in _request
    raise ex.DataException("Couldn't parse the JSON response received from the server: {content}".format(
        content=r.content))
BotKapil.Broker.SmartApi.smartExceptions.DataException: Couldn't parse the JSON response received from the server: b'Access denied because of exceeding access rate'
09-04-25 00:50:56 - ERROR - Couldn't parse the JSON response received from the server: b'Access denied because of exceeding access rate'
Traceback (most recent call last):
  File "C:\Users\sumit\BotKapil\BotKapil\Broker\SmartApi\smartConnect.py", line 230, in _request
    data = json.loads(r.content.decode("utf8"))
  File "C:\Users\sumit\AppData\Local\Programs\Python\Python313\Lib\json\__init__.py", line 346, in loads
    return _default_decoder.decode(s)
           ~~~~~~~~~~~~~~~~~~~~~~~^^^
  File "C:\Users\sumit\AppData\Local\Programs\Python\Python313\Lib\json\decoder.py", line 345, in decode
    obj, end = self.raw_decode(s, idx=_w(s, 0).end())
               ~~~~~~~~~~~~~~~^^^^^^^^^^^^^^^^^^^^^^^
  File "C:\Users\sumit\AppData\Local\Programs\Python\Python313\Lib\json\decoder.py", line 363, in raw_decode
    raise JSONDecodeError("Expecting value", s, err.value) from None
json.decoder.JSONDecodeError: Expecting value: line 1 column 1 (char 0)

During handling of the above exception, another exception occurred:

Traceback (most recent call last):
  File "C:\Users\sumit\BotKapil\BotKapil\utility\utility.py", line 156, in processorder
    broker= Angel.HTTP(1)
  File "C:\Users\sumit\BotKapil\BotKapil\Broker\Angelsdk.py", line 171, in __init__
    super().__init__(self,api_key , username ,pwd,token)
    ~~~~~~~~~~~~~~~~^^^^^^^^^^^^^^^^^^^^^^^^^^^^^^^^^^^^
  File "C:\Users\sumit\BotKapil\BotKapil\Broker\Angelsdk.py", line 120, in __init__
    self.smartAPI_Login()
    ~~~~~~~~~~~~~~~~~~~^^
  File "C:\Users\sumit\BotKapil\BotKapil\Broker\Angelsdk.py", line 131, in smartAPI_Login
    data = self.smartApi.generateSession(self.username, self.pwd, totp)
  File "C:\Users\sumit\BotKapil\BotKapil\Broker\SmartApi\smartConnect.py", line 271, in generateSession
    loginResultObject=self._postRequest("api.login",params)
  File "C:\Users\sumit\BotKapil\BotKapil\Broker\SmartApi\smartConnect.py", line 263, in _postRequest
    return self._request(route, "POST", params)
           ~~~~~~~~~~~~~^^^^^^^^^^^^^^^^^^^^^^^
  File "C:\Users\sumit\BotKapil\BotKapil\Broker\SmartApi\smartConnect.py", line 233, in _request
    raise ex.DataException("Couldn't parse the JSON response received from the server: {content}".format(
        content=r.content))
BotKapil.Broker.SmartApi.smartExceptions.DataException: Couldn't parse the JSON response received from the server: b'Access denied because of exceeding access rate'
09-04-25 00:50:56 - ERROR - Couldn't parse the JSON response received from the server: b'Access denied because of exceeding access rate'
Traceback (most recent call last):
  File "C:\Users\sumit\BotKapil\BotKapil\Broker\SmartApi\smartConnect.py", line 230, in _request
    data = json.loads(r.content.decode("utf8"))
  File "C:\Users\sumit\AppData\Local\Programs\Python\Python313\Lib\json\__init__.py", line 346, in loads
    return _default_decoder.decode(s)
           ~~~~~~~~~~~~~~~~~~~~~~~^^^
  File "C:\Users\sumit\AppData\Local\Programs\Python\Python313\Lib\json\decoder.py", line 345, in decode
    obj, end = self.raw_decode(s, idx=_w(s, 0).end())
               ~~~~~~~~~~~~~~~^^^^^^^^^^^^^^^^^^^^^^^
  File "C:\Users\sumit\AppData\Local\Programs\Python\Python313\Lib\json\decoder.py", line 363, in raw_decode
    raise JSONDecodeError("Expecting value", s, err.value) from None
json.decoder.JSONDecodeError: Expecting value: line 1 column 1 (char 0)

During handling of the above exception, another exception occurred:

Traceback (most recent call last):
  File "C:\Users\sumit\BotKapil\BotKapil\utility\utility.py", line 156, in processorder
    broker= Angel.HTTP(1)
  File "C:\Users\sumit\BotKapil\BotKapil\Broker\Angelsdk.py", line 171, in __init__
    super().__init__(self,api_key , username ,pwd,token)
    ~~~~~~~~~~~~~~~~^^^^^^^^^^^^^^^^^^^^^^^^^^^^^^^^^^^^
  File "C:\Users\sumit\BotKapil\BotKapil\Broker\Angelsdk.py", line 120, in __init__
    self.smartAPI_Login()
    ~~~~~~~~~~~~~~~~~~~^^
  File "C:\Users\sumit\BotKapil\BotKapil\Broker\Angelsdk.py", line 131, in smartAPI_Login
    data = self.smartApi.generateSession(self.username, self.pwd, totp)
  File "C:\Users\sumit\BotKapil\BotKapil\Broker\SmartApi\smartConnect.py", line 271, in generateSession
    loginResultObject=self._postRequest("api.login",params)
  File "C:\Users\sumit\BotKapil\BotKapil\Broker\SmartApi\smartConnect.py", line 263, in _postRequest
    return self._request(route, "POST", params)
           ~~~~~~~~~~~~~^^^^^^^^^^^^^^^^^^^^^^^
  File "C:\Users\sumit\BotKapil\BotKapil\Broker\SmartApi\smartConnect.py", line 233, in _request
    raise ex.DataException("Couldn't parse the JSON response received from the server: {content}".format(
        content=r.content))
BotKapil.Broker.SmartApi.smartExceptions.DataException: Couldn't parse the JSON response received from the server: b'Access denied because of exceeding access rate'
09-04-25 00:50:56 - ERROR - Couldn't parse the JSON response received from the server: b'Access denied because of exceeding access rate'
Traceback (most recent call last):
  File "C:\Users\sumit\BotKapil\BotKapil\Broker\SmartApi\smartConnect.py", line 230, in _request
    data = json.loads(r.content.decode("utf8"))
  File "C:\Users\sumit\AppData\Local\Programs\Python\Python313\Lib\json\__init__.py", line 346, in loads
    return _default_decoder.decode(s)
           ~~~~~~~~~~~~~~~~~~~~~~~^^^
  File "C:\Users\sumit\AppData\Local\Programs\Python\Python313\Lib\json\decoder.py", line 345, in decode
    obj, end = self.raw_decode(s, idx=_w(s, 0).end())
               ~~~~~~~~~~~~~~~^^^^^^^^^^^^^^^^^^^^^^^
  File "C:\Users\sumit\AppData\Local\Programs\Python\Python313\Lib\json\decoder.py", line 363, in raw_decode
    raise JSONDecodeError("Expecting value", s, err.value) from None
json.decoder.JSONDecodeError: Expecting value: line 1 column 1 (char 0)

During handling of the above exception, another exception occurred:

Traceback (most recent call last):
  File "C:\Users\sumit\BotKapil\BotKapil\utility\utility.py", line 156, in processorder
    broker= Angel.HTTP(1)
  File "C:\Users\sumit\BotKapil\BotKapil\Broker\Angelsdk.py", line 171, in __init__
    super().__init__(self,api_key , username ,pwd,token)
    ~~~~~~~~~~~~~~~~^^^^^^^^^^^^^^^^^^^^^^^^^^^^^^^^^^^^
  File "C:\Users\sumit\BotKapil\BotKapil\Broker\Angelsdk.py", line 120, in __init__
    self.smartAPI_Login()
    ~~~~~~~~~~~~~~~~~~~^^
  File "C:\Users\sumit\BotKapil\BotKapil\Broker\Angelsdk.py", line 131, in smartAPI_Login
    data = self.smartApi.generateSession(self.username, self.pwd, totp)
  File "C:\Users\sumit\BotKapil\BotKapil\Broker\SmartApi\smartConnect.py", line 271, in generateSession
    loginResultObject=self._postRequest("api.login",params)
  File "C:\Users\sumit\BotKapil\BotKapil\Broker\SmartApi\smartConnect.py", line 263, in _postRequest
    return self._request(route, "POST", params)
           ~~~~~~~~~~~~~^^^^^^^^^^^^^^^^^^^^^^^
  File "C:\Users\sumit\BotKapil\BotKapil\Broker\SmartApi\smartConnect.py", line 233, in _request
    raise ex.DataException("Couldn't parse the JSON response received from the server: {content}".format(
        content=r.content))
BotKapil.Broker.SmartApi.smartExceptions.DataException: Couldn't parse the JSON response received from the server: b'Access denied because of exceeding access rate'
09-04-25 00:50:56 - ERROR - Couldn't parse the JSON response received from the server: b'Access denied because of exceeding access rate'
Traceback (most recent call last):
  File "C:\Users\sumit\BotKapil\BotKapil\Broker\SmartApi\smartConnect.py", line 230, in _request
    data = json.loads(r.content.decode("utf8"))
  File "C:\Users\sumit\AppData\Local\Programs\Python\Python313\Lib\json\__init__.py", line 346, in loads
    return _default_decoder.decode(s)
           ~~~~~~~~~~~~~~~~~~~~~~~^^^
  File "C:\Users\sumit\AppData\Local\Programs\Python\Python313\Lib\json\decoder.py", line 345, in decode
    obj, end = self.raw_decode(s, idx=_w(s, 0).end())
               ~~~~~~~~~~~~~~~^^^^^^^^^^^^^^^^^^^^^^^
  File "C:\Users\sumit\AppData\Local\Programs\Python\Python313\Lib\json\decoder.py", line 363, in raw_decode
    raise JSONDecodeError("Expecting value", s, err.value) from None
json.decoder.JSONDecodeError: Expecting value: line 1 column 1 (char 0)

During handling of the above exception, another exception occurred:

Traceback (most recent call last):
  File "C:\Users\sumit\BotKapil\BotKapil\utility\utility.py", line 156, in processorder
    broker= Angel.HTTP(1)
  File "C:\Users\sumit\BotKapil\BotKapil\Broker\Angelsdk.py", line 171, in __init__
    super().__init__(self,api_key , username ,pwd,token)
    ~~~~~~~~~~~~~~~~^^^^^^^^^^^^^^^^^^^^^^^^^^^^^^^^^^^^
  File "C:\Users\sumit\BotKapil\BotKapil\Broker\Angelsdk.py", line 120, in __init__
    self.smartAPI_Login()
    ~~~~~~~~~~~~~~~~~~~^^
  File "C:\Users\sumit\BotKapil\BotKapil\Broker\Angelsdk.py", line 131, in smartAPI_Login
    data = self.smartApi.generateSession(self.username, self.pwd, totp)
  File "C:\Users\sumit\BotKapil\BotKapil\Broker\SmartApi\smartConnect.py", line 271, in generateSession
    loginResultObject=self._postRequest("api.login",params)
  File "C:\Users\sumit\BotKapil\BotKapil\Broker\SmartApi\smartConnect.py", line 263, in _postRequest
    return self._request(route, "POST", params)
           ~~~~~~~~~~~~~^^^^^^^^^^^^^^^^^^^^^^^
  File "C:\Users\sumit\BotKapil\BotKapil\Broker\SmartApi\smartConnect.py", line 233, in _request
    raise ex.DataException("Couldn't parse the JSON response received from the server: {content}".format(
        content=r.content))
BotKapil.Broker.SmartApi.smartExceptions.DataException: Couldn't parse the JSON response received from the server: b'Access denied because of exceeding access rate'
09-04-25 00:53:18 - ERROR - Couldn't parse the JSON response received from the server: b'Access denied because of exceeding access rate'
Traceback (most recent call last):
  File "C:\Users\sumit\BotKapil\BotKapil\Broker\SmartApi\smartConnect.py", line 230, in _request
    data = json.loads(r.content.decode("utf8"))
  File "C:\Users\sumit\AppData\Local\Programs\Python\Python313\Lib\json\__init__.py", line 346, in loads
    return _default_decoder.decode(s)
           ~~~~~~~~~~~~~~~~~~~~~~~^^^
  File "C:\Users\sumit\AppData\Local\Programs\Python\Python313\Lib\json\decoder.py", line 345, in decode
    obj, end = self.raw_decode(s, idx=_w(s, 0).end())
               ~~~~~~~~~~~~~~~^^^^^^^^^^^^^^^^^^^^^^^
  File "C:\Users\sumit\AppData\Local\Programs\Python\Python313\Lib\json\decoder.py", line 363, in raw_decode
    raise JSONDecodeError("Expecting value", s, err.value) from None
json.decoder.JSONDecodeError: Expecting value: line 1 column 1 (char 0)

During handling of the above exception, another exception occurred:

Traceback (most recent call last):
  File "C:\Users\sumit\BotKapil\BotKapil\utility\utility.py", line 156, in processorder
    broker= Angel.HTTP(1)
  File "C:\Users\sumit\BotKapil\BotKapil\Broker\Angelsdk.py", line 171, in __init__
    super().__init__(self,api_key , username ,pwd,token)
    ~~~~~~~~~~~~~~~~^^^^^^^^^^^^^^^^^^^^^^^^^^^^^^^^^^^^
  File "C:\Users\sumit\BotKapil\BotKapil\Broker\Angelsdk.py", line 120, in __init__
    self.smartAPI_Login()
    ~~~~~~~~~~~~~~~~~~~^^
  File "C:\Users\sumit\BotKapil\BotKapil\Broker\Angelsdk.py", line 131, in smartAPI_Login
    data = self.smartApi.generateSession(self.username, self.pwd, totp)
  File "C:\Users\sumit\BotKapil\BotKapil\Broker\SmartApi\smartConnect.py", line 271, in generateSession
    loginResultObject=self._postRequest("api.login",params)
  File "C:\Users\sumit\BotKapil\BotKapil\Broker\SmartApi\smartConnect.py", line 263, in _postRequest
    return self._request(route, "POST", params)
           ~~~~~~~~~~~~~^^^^^^^^^^^^^^^^^^^^^^^
  File "C:\Users\sumit\BotKapil\BotKapil\Broker\SmartApi\smartConnect.py", line 233, in _request
    raise ex.DataException("Couldn't parse the JSON response received from the server: {content}".format(
        content=r.content))
BotKapil.Broker.SmartApi.smartExceptions.DataException: Couldn't parse the JSON response received from the server: b'Access denied because of exceeding access rate'
09-04-25 00:53:18 - ERROR - Couldn't parse the JSON response received from the server: b'Access denied because of exceeding access rate'
Traceback (most recent call last):
  File "C:\Users\sumit\BotKapil\BotKapil\Broker\SmartApi\smartConnect.py", line 230, in _request
    data = json.loads(r.content.decode("utf8"))
  File "C:\Users\sumit\AppData\Local\Programs\Python\Python313\Lib\json\__init__.py", line 346, in loads
    return _default_decoder.decode(s)
           ~~~~~~~~~~~~~~~~~~~~~~~^^^
  File "C:\Users\sumit\AppData\Local\Programs\Python\Python313\Lib\json\decoder.py", line 345, in decode
    obj, end = self.raw_decode(s, idx=_w(s, 0).end())
               ~~~~~~~~~~~~~~~^^^^^^^^^^^^^^^^^^^^^^^
  File "C:\Users\sumit\AppData\Local\Programs\Python\Python313\Lib\json\decoder.py", line 363, in raw_decode
    raise JSONDecodeError("Expecting value", s, err.value) from None
json.decoder.JSONDecodeError: Expecting value: line 1 column 1 (char 0)

During handling of the above exception, another exception occurred:

Traceback (most recent call last):
  File "C:\Users\sumit\BotKapil\BotKapil\utility\utility.py", line 156, in processorder
    broker= Angel.HTTP(1)
  File "C:\Users\sumit\BotKapil\BotKapil\Broker\Angelsdk.py", line 171, in __init__
    super().__init__(self,api_key , username ,pwd,token)
    ~~~~~~~~~~~~~~~~^^^^^^^^^^^^^^^^^^^^^^^^^^^^^^^^^^^^
  File "C:\Users\sumit\BotKapil\BotKapil\Broker\Angelsdk.py", line 120, in __init__
    self.smartAPI_Login()
    ~~~~~~~~~~~~~~~~~~~^^
  File "C:\Users\sumit\BotKapil\BotKapil\Broker\Angelsdk.py", line 131, in smartAPI_Login
    data = self.smartApi.generateSession(self.username, self.pwd, totp)
  File "C:\Users\sumit\BotKapil\BotKapil\Broker\SmartApi\smartConnect.py", line 271, in generateSession
    loginResultObject=self._postRequest("api.login",params)
  File "C:\Users\sumit\BotKapil\BotKapil\Broker\SmartApi\smartConnect.py", line 263, in _postRequest
    return self._request(route, "POST", params)
           ~~~~~~~~~~~~~^^^^^^^^^^^^^^^^^^^^^^^
  File "C:\Users\sumit\BotKapil\BotKapil\Broker\SmartApi\smartConnect.py", line 233, in _request
    raise ex.DataException("Couldn't parse the JSON response received from the server: {content}".format(
        content=r.content))
BotKapil.Broker.SmartApi.smartExceptions.DataException: Couldn't parse the JSON response received from the server: b'Access denied because of exceeding access rate'
09-04-25 00:53:18 - ERROR - Couldn't parse the JSON response received from the server: b'Access denied because of exceeding access rate'
Traceback (most recent call last):
  File "C:\Users\sumit\BotKapil\BotKapil\Broker\SmartApi\smartConnect.py", line 230, in _request
    data = json.loads(r.content.decode("utf8"))
  File "C:\Users\sumit\AppData\Local\Programs\Python\Python313\Lib\json\__init__.py", line 346, in loads
    return _default_decoder.decode(s)
           ~~~~~~~~~~~~~~~~~~~~~~~^^^
  File "C:\Users\sumit\AppData\Local\Programs\Python\Python313\Lib\json\decoder.py", line 345, in decode
    obj, end = self.raw_decode(s, idx=_w(s, 0).end())
               ~~~~~~~~~~~~~~~^^^^^^^^^^^^^^^^^^^^^^^
  File "C:\Users\sumit\AppData\Local\Programs\Python\Python313\Lib\json\decoder.py", line 363, in raw_decode
    raise JSONDecodeError("Expecting value", s, err.value) from None
json.decoder.JSONDecodeError: Expecting value: line 1 column 1 (char 0)

During handling of the above exception, another exception occurred:

Traceback (most recent call last):
  File "C:\Users\sumit\BotKapil\BotKapil\utility\utility.py", line 156, in processorder
    broker= Angel.HTTP(1)
  File "C:\Users\sumit\BotKapil\BotKapil\Broker\Angelsdk.py", line 171, in __init__
    super().__init__(self,api_key , username ,pwd,token)
    ~~~~~~~~~~~~~~~~^^^^^^^^^^^^^^^^^^^^^^^^^^^^^^^^^^^^
  File "C:\Users\sumit\BotKapil\BotKapil\Broker\Angelsdk.py", line 120, in __init__
    self.smartAPI_Login()
    ~~~~~~~~~~~~~~~~~~~^^
  File "C:\Users\sumit\BotKapil\BotKapil\Broker\Angelsdk.py", line 131, in smartAPI_Login
    data = self.smartApi.generateSession(self.username, self.pwd, totp)
  File "C:\Users\sumit\BotKapil\BotKapil\Broker\SmartApi\smartConnect.py", line 271, in generateSession
    loginResultObject=self._postRequest("api.login",params)
  File "C:\Users\sumit\BotKapil\BotKapil\Broker\SmartApi\smartConnect.py", line 263, in _postRequest
    return self._request(route, "POST", params)
           ~~~~~~~~~~~~~^^^^^^^^^^^^^^^^^^^^^^^
  File "C:\Users\sumit\BotKapil\BotKapil\Broker\SmartApi\smartConnect.py", line 233, in _request
    raise ex.DataException("Couldn't parse the JSON response received from the server: {content}".format(
        content=r.content))
BotKapil.Broker.SmartApi.smartExceptions.DataException: Couldn't parse the JSON response received from the server: b'Access denied because of exceeding access rate'
09-04-25 00:53:18 - ERROR - Couldn't parse the JSON response received from the server: b'Access denied because of exceeding access rate'
Traceback (most recent call last):
  File "C:\Users\sumit\BotKapil\BotKapil\Broker\SmartApi\smartConnect.py", line 230, in _request
    data = json.loads(r.content.decode("utf8"))
  File "C:\Users\sumit\AppData\Local\Programs\Python\Python313\Lib\json\__init__.py", line 346, in loads
    return _default_decoder.decode(s)
           ~~~~~~~~~~~~~~~~~~~~~~~^^^
  File "C:\Users\sumit\AppData\Local\Programs\Python\Python313\Lib\json\decoder.py", line 345, in decode
    obj, end = self.raw_decode(s, idx=_w(s, 0).end())
               ~~~~~~~~~~~~~~~^^^^^^^^^^^^^^^^^^^^^^^
  File "C:\Users\sumit\AppData\Local\Programs\Python\Python313\Lib\json\decoder.py", line 363, in raw_decode
    raise JSONDecodeError("Expecting value", s, err.value) from None
json.decoder.JSONDecodeError: Expecting value: line 1 column 1 (char 0)

During handling of the above exception, another exception occurred:

Traceback (most recent call last):
  File "C:\Users\sumit\BotKapil\BotKapil\utility\utility.py", line 156, in processorder
    broker= Angel.HTTP(1)
  File "C:\Users\sumit\BotKapil\BotKapil\Broker\Angelsdk.py", line 171, in __init__
    super().__init__(self,api_key , username ,pwd,token)
    ~~~~~~~~~~~~~~~~^^^^^^^^^^^^^^^^^^^^^^^^^^^^^^^^^^^^
  File "C:\Users\sumit\BotKapil\BotKapil\Broker\Angelsdk.py", line 120, in __init__
    self.smartAPI_Login()
    ~~~~~~~~~~~~~~~~~~~^^
  File "C:\Users\sumit\BotKapil\BotKapil\Broker\Angelsdk.py", line 131, in smartAPI_Login
    data = self.smartApi.generateSession(self.username, self.pwd, totp)
  File "C:\Users\sumit\BotKapil\BotKapil\Broker\SmartApi\smartConnect.py", line 271, in generateSession
    loginResultObject=self._postRequest("api.login",params)
  File "C:\Users\sumit\BotKapil\BotKapil\Broker\SmartApi\smartConnect.py", line 263, in _postRequest
    return self._request(route, "POST", params)
           ~~~~~~~~~~~~~^^^^^^^^^^^^^^^^^^^^^^^
  File "C:\Users\sumit\BotKapil\BotKapil\Broker\SmartApi\smartConnect.py", line 233, in _request
    raise ex.DataException("Couldn't parse the JSON response received from the server: {content}".format(
        content=r.content))
BotKapil.Broker.SmartApi.smartExceptions.DataException: Couldn't parse the JSON response received from the server: b'Access denied because of exceeding access rate'
09-04-25 00:58:16 - ERROR - check the orderobject function No columns to parse from file
09-04-25 01:00:16 - ERROR - check the orderobject function No columns to parse from file
09-04-25 01:01:22 - ERROR - check the orderobject function No columns to parse from file
09-04-25 01:05:24 - ERROR - check the orderobject function No columns to parse from file
09-04-25 01:13:08 - ERROR - check the orderobject function No columns to parse from file
09-04-25 01:25:27 - ERROR - check the orderobject function No columns to parse from file
09-04-25 01:32:24 - ERROR - check the orderobject function No columns to parse from file
09-04-25 01:46:31 - ERROR - check the orderobject function No columns to parse from file
09-04-25 01:48:56 - ERROR - check the orderobject function No columns to parse from file
09-04-25 01:52:15 - ERROR - check the orderobject function No columns to parse from file
